Workbook

Sheet DASHBOARD
B6: DASHBOARD | F6: TOTAL PROFIT
F7: =SUM(F12+F17+F22) -> 419.90765
B9: Maya Bairey
B11: TOTAL PAID | D11: ROYALTIES OWED | F11: PROFIT
B12: =SUMIFS(Transactions!K:K, Transactions!C:C, B9, Transactions!E:E, "Payment")*-1 -> 0 | D12: =SUMIFS(Transactions!K:K, Transactions!C:C, B9, Transactions!E:E, "<>Payment")+SUMIFS(Transactions!K:K, Transactions!C:C, B9, Transactions!E:E, "Payment") -> 507.20073 | F12: =SUMIFS(Transactions!K:K, Transactions!C:C, B9, Transactions!E:E, "<>Payment", Transactions!L:L, ">0")*AVERAGEIFS(Transactions!L:L, Transactions!C:C, B9, Transactions!E:E, "<>Payment") -> 392.31265
B14: Sulima Malzin
B16: TOTAL PAID | D16: ROYALTIES OWED | F16: PROFIT
B17: =SUMIFS(Transactions!K:K, Transactions!C:C, B14, Transactions!E:E, "Payment")*-1 -> 274.47 | D17: =SUMIFS(Transactions!K:K, Transactions!C:C, B14, Transactions!E:E, "<>Payment")+SUMIFS(Transactions!K:K, Transactions!C:C, B14, Transactions!E:E, "Payment") -> 27.97154 | F17: =SUMIFS(Transactions!K:K, Transactions!C:C, B14, Transactions!E:E, "<>Payment", Transactions!L:L, ">0")*AVERAGEIFS(Transactions!L:L, Transactions!C:C, B14, Transactions!E:E, "<>Payment") -> 0
B19: Carolyn Martin
B21: TOTAL PAID | D21: ROYALTIES OWED | F21: PROFIT
B22: =SUMIFS(Transactions!K:K, Transactions!C:C, B19, Transactions!E:E, "Payment")*-1 -> 0 | D22: =SUMIFS(Transactions!K:K, Transactions!C:C, B19, Transactions!E:E, "<>Payment")+SUMIFS(Transactions!K:K, Transactions!C:C, B19, Transactions!E:E, "Payment") -> 55.19 | F22: =SUMIFS(Transactions!K:K, Transactions!C:C, B19, Transactions!E:E, "<>Payment", Transactions!L:L, ">0")*AVERAGEIFS(Transactions!L:L, Transactions!C:C, B19, Transactions!E:E, "<>Payment") -> 27.595

Sheet Royalty Report
G2: 10350 North Vancouver Way, Suite 5518 Portland, Oregon 97217 info@linguaink.com +1 (503) 847-9860
B6: Royalty Report | G6: 45658 | H6: through | L6: 46022
B9: Maya Bairey | H9: Author Royalty Rate | L9: 1
B11: TOTAL EARNINGS | C11: PAPERBACKS | E11: EBOOKS | F11: KENP | G11: UNITS SOLD | L11: TOTAL DUE TO AUTHOR | O11: LAST BALANCE
B12: =SUMIFS(Transactions!K:K, Transactions!C:C, B9, Transactions!A:A, ">="&G6, Transactions!A:A, "<="&L6, Transactions!H:H, "<>Payment", Transactions!K:K, ">=0") -> 156.32968 | C12: =SUMIFS( Transactions!K:K, Transactions!C:C, B9, Transactions!D:D, "Paperback", Transactions!A:A, ">="&G6, Transactions!A:A, "<="&L6, Transactions!H:H, "<>Payment", Transactions!K:K, ">=0") -> 144.05 | E12: =SUMIFS( Transactions!K:K, Transactions!C:C, B9, Transactions!D:D, "Ebook", Transactions!A:A, ">="&G6, Transactions!A:A, "<="&L6, Transactions!H:H, "<>Payment", Transactions!K:K, ">=0") -> 12.279682 | F12: =SUMIFS(Transactions!K:K, Transactions!C:C, B9, Transactions!D:D, "Ebook", Transactions!E:E, "KENP", Transactions!A:A, ">="&G6, Transactions!A:A, "<="&L6, Transactions!H:H, "<>Payment", Transactions!K:K, ">=0") -> 8.749682 | G12: =SUMIFS(Transactions!G:G, Transactions!C:C, B9, Transactions!A:A, ">="&G6, Transactions!A:A, "<="&L6) -> 5632 | L12: =SUMIFS(Transactions!K:K, Transactions!C:C, B9, Transactions!A:A, ">="&G6, Transactions!A:A, "<="&L6) * L9 + O12 -> 156.32968 | O12: 0
B14: ITEMIZATION
B15: Month | C15: Title | E15: Format | F15: Transaction | G15: Marketplace | H15: Units | L15: Net Royalty
B16: {=IF(OR(G6="", L6=""), "", _xlfn._xlws.FILTER( Transactions!A2:K978, (Transactions!C2:C978=B9) * (Transactions!A2:A978>=G6) * (Transactions!A2:A978<=L6), "No records" ) )} -> 45658 | C16: Painting Celia | D16: Maya Bairey | E16: Ebook | F16: KENP | G16: Amazon.com | H16: 1 | I16: 0 | J16: 0 | K16: 0 | L16: 0.004394
B17: 45689 | C17: Painting Celia | D17: Maya Bairey | E17: Paperback | F17: Purchase | G17: Amazon.com | H17: 1 | I17: 0 | J17: 1 | K17: 0.6 | L17: 1.55
B18: 45689 | C18: Painting Celia | D18: Maya Bairey | E18: Paperback | F18: Purchase | G18: Amazon.com | H18: 1 | I18: 0 | J18: 1 | K18: 0.6 | L18: 1.55
B19: 45689 | C19: Painting Celia | D19: Maya Bairey | E19: Ebook | F19: KENP | G19: Amazon.com | H19: 2 | I19: 0 | J19: 0 | K19: 0 | L19: 0.008788
B20: 45717 | C20: Painting Celia | D20: Maya Bairey | E20: Ebook | F20: Free promo | G20: Amazon.co.uk | H20: 1 | I20: 0 | J20: 1 | K20: 0.7 | L20: 0
B21: 45717 | C21: Painting Celia | D21: Maya Bairey | E21: Paperback | F21: Purchase | G21: Amazon.com | H21: 1 | I21: 0 | J21: 1 | K21: 0.6 | L21: 1.11
B22: 45717 | C22: Painting Celia | D22: Maya Bairey | E22: Paperback | F22: Purchase | G22: Amazon.com | H22: 1 | I22: 0 | J22: 1 | K22: 0.6 | L22: 1.11
B23: 45717 | C23: Painting Celia | D23: Maya Bairey | E23: Paperback | F23: Purchase | G23: In person | H23: 1 | I23: 0 | J23: 1 | K23: 1 | L23: 15
B24: 45717 | C24: Painting Celia | D24: Maya Bairey | E24: Paperback | F24: Purchase | G24: In person | H24: 1 | I24: 0 | J24: 1 | K24: 1 | L24: 15
B25: 45717 | C25: Painting Celia | D25: Maya Bairey | E25: Paperback | F25: Purchase | G25: In person | H25: 1 | I25: 0 | J25: 1 | K25: 1 | L25: 15
B26: 45717 | C26: Painting Celia | D26: Maya Bairey | E26: Ebook | F26: Free promo | G26: Amazon.com | H26: 2 | I26: 0 | J26: 2 | K26: 0.35 | L26: 0
B27: 45717 | C27: Painting Celia | D27: Maya Bairey | E27: Ebook | F27: Purchase | G27: Amazon.com | H27: 2 | I27: 0 | J27: 2 | K27: 0.35 | L27: 0.7
B28: 45717 | C28: Painting Celia | D28: Maya Bairey | E28: Ebook | F28: Free promo | G28: Amazon.com | H28: 9 | I28: 0 | J28: 9 | K28: 0.7 | L28: 0
... B87: 45992 | C87: Painting Celia | D87: Maya Bairey | E87: Ebook | F87: Purchase | G87: Amazon.ca | H87: 1 | I87: 0 | J87: 1 | K87: 0.7 | L87: 2.83

Sheet Maya
A1: TOTAL SALES
B3: =B11 -> Vella | C3: =SUM(K:K) -> 507.20073
B4: Ebook | C4: =SUMIFS(K10:K1000, D10:D1000, "Ebook", E10:E1000, "<>KENP") -> 49.96
B5: Print | C5: =SUMIFS(K10:K1000, D10:D1000, "Paperback") -> 386.88
B6: KENP | C6: =SUMIFS(K10:K1000, D10:D1000, "Ebook", E10:E1000, "KENP") -> 63.050734
A10: Date | B10: Title | C10: Author | D10: Format | E10: Type | F10: Marketplace | G10: Units Sold | H10: Units Refunded | I10: Net Units Sold | J10: Payout | K10: Earnings
A11: {=_xlfn._xlws.FILTER(Transactions!A2:K978, Transactions!C2:C978="Maya Bairey", "No records")} -> 45078 | B11: Vella | C11: Maya Bairey | D11: Vella | E11: KENP | F11: Amazon.com | G11: 0 | H11: 0 | I11: 0 | J11: 0 | K11: 7.31
A12: 45383 | B12: Painting Celia | C12: Maya Bairey | D12: Paperback | E12: Purchase | F12: In person | G12: 1 | H12: 0 | I12: 1 | J12: 1 | K12: 9.48
A13: 45383 | B13: Painting Celia | C13: Maya Bairey | D13: Paperback | E13: Purchase | F13: In person | G13: 1 | H13: 0 | I13: 1 | J13: 1 | K13: 9.48
A14: 45383 | B14: Painting Celia | C14: Maya Bairey | D14: Paperback | E14: Purchase | F14: In person | G14: 1 | H14: 0 | I14: 1 | J14: 1 | K14: 9.48
A15: 45383 | B15: Painting Celia | C15: Maya Bairey | D15: Paperback | E15: Purchase | F15: In person | G15: 1 | H15: 0 | I15: 1 | J15: 1 | K15: 9.48
A16: 45383 | B16: Painting Celia | C16: Maya Bairey | D16: Paperback | E16: Purchase | F16: In person | G16: 1 | H16: 0 | I16: 1 | J16: 1 | K16: 9.48
A17: 45413 | B17: Painting Celia | C17: Maya Bairey | D17: Ebook | E17: Pre-order | F17: Amazon.com | G17: 23 | H17: 0 | I17: 23 | J17: 0.35 | K17: 8.05
A18: 45413 | B18: Painting Celia | C18: Maya Bairey | D18: Ebook | E18: Goodreads | F18: Amazon.com | G18: 100 | H18: 0 | I18: 100 | J18: 0.35 | K18: 0
A19: 45413 | B19: Painting Celia | C19: Maya Bairey | D19: Ebook | E19: Free promo | F19: Amazon.com | G19: 304 | H19: 0 | I19: 304 | J19: 0.35 | K19: 0
A20: 45413 | B20: Painting Celia | C20: Maya Bairey | D20: Ebook | E20: Free promo | F20: Amazon.com | G20: 1 | H20: 0 | I20: 1 | J20: 0.35 | K20: 0
A21: 45413 | B21: Painting Celia | C21: Maya Bairey | D21: Ebook | E21: Free promo | F21: Amazon.com | G21: 2 | H21: 0 | I21: 2 | J21: 0.35 | K21: 0
A22: 45413 | B22: Painting Celia | C22: Maya Bairey | D22: Ebook | E22: Purchase | F22: Amazon.com | G22: 96 | H22: 0 | I22: 96 | J22: 0.35 | K22: 33.6
A23: 45413 | B23: Painting Celia | C23: Maya Bairey | D23: Ebook | E23: Free promo | F23: Amazon.co.uk | G23: 2 | H23: 0 | I23: 2 | J23: 0.35 | K23: 0
... A160: 45992 | B160: Painting Celia | C160: Maya Bairey | D160: Ebook | E160: Purchase | F160: Amazon.ca | G160: 1 | H160: 0 | I160: 1 | J160: 0.7 | K160: 2.83

Sheet Sulima
A1: TOTAL SALES
B3: All Books | C3: =SUM(K:K) -> 27.97154
B4: Ebook | C4: =SUMIFS(K10:K1000, D10:D1000, "Ebook", E10:E1000, "<>KENP") -> 7.7
B5: Print | C5: =SUMIFS(K10:K1000, D10:D1000, "Paperback") -> 127.32
B6: KENP | C6: =SUMIFS(K10:K1000, D10:D1000, "Ebook", E10:E1000, "KENP") -> 1.87154
A10: Date | B10: Title | C10: Author | D10: Format | E10: Type | F10: Marketplace | G10: Units Sold | H10: Units Refunded | I10: Net Units Sold | J10: Payout | K10: Earnings
A11: {=_xlfn._xlws.FILTER(Transactions!A2:K978, Transactions!C2:C978="Sulima Malzin", "No records")} -> 44805 | B11: (multiple) | C11: Sulima Malzin | D11: (multiple) | E11: Payment | F11: (multiple) | G11: 0 | H11: 0 | I11: 0 | J11: 0 | K11: 242.51
A12: 44850 | B12: (multiple) | C12: Sulima Malzin | D12: (multiple) | E12: Payment | F12: (multiple) | G12: 0 | H12: 0 | I12: 0 | J12: 0 | K12: -40
A13: 44957 | B13: (multiple) | C13: Sulima Malzin | D13: (multiple) | E13: Payment | F13: (multiple) | G13: 0 | H13: 0 | I13: 0 | J13: 0 | K13: -29
A14: 45027 | B14: (multiple) | C14: Sulima Malzin | D14: (multiple) | E14: Payment | F14: (multiple) | G14: 0 | H14: 0 | I14: 0 | J14: 0 | K14: -29
A15: 45047 | B15: Arms Filled with Bittersweet | C15: Sulima Malzin | D15: Ebook | E15: Pre-order | F15: Amazon.com | G15: 15 | H15: 0 | I15: 15 | J15: 0.35 | K15: 5.25
A16: 45047 | B16: Arms Filled with Bittersweet | C16: Sulima Malzin | D16: Ebook | E16: Free promo | F16: Amazon.com | G16: 55 | H16: 0 | I16: 55 | J16: 0.35 | K16: 0
A17: 45047 | B17: Arms Filled with Bittersweet | C17: Sulima Malzin | D17: Ebook | E17: Free promo | F17: Amazon.com | G17: 1 | H17: 0 | I17: 1 | J17: 0.35 | K17: 0
A18: 45047 | B18: Arms Filled with Bittersweet | C18: Sulima Malzin | D18: Ebook | E18: Free promo | F18: Amazon.co.uk | G18: 2 | H18: 0 | I18: 2 | J18: 0.35 | K18: 0
A19: 45047 | B19: Arms Filled with Bittersweet | C19: Sulima Malzin | D19: Ebook | E19: Free price match | F19: Amazon.ca | G19: 1 | H19: 0 | I19: 1 | J19: 0.35 | K19: 0
A20: 45047 | B20: Arms Filled with Bittersweet | C20: Sulima Malzin | D20: Ebook | E20: Free promo | F20: Amazon.ca | G20: 1 | H20: 0 | I20: 1 | J20: 0.35 | K20: 0
A21: 45047 | B21: Arms Filled with Bittersweet | C21: Sulima Malzin | D21: Ebook | E21: Free promo | F21: Amazon.in | G21: 1 | H21: 0 | I21: 1 | J21: 0.35 | K21: 0
A22: 45047 | B22: Arms Filled with Bittersweet | C22: Sulima Malzin | D22: Paperback | E22: Purchase | F22: Amazon.com | G22: 1 | H22: 0 | I22: 1 | J22: 0.6 | K22: 5.64
A23: 45047 | B23: Arms Filled with Bittersweet | C23: Sulima Malzin | D23: Paperback | E23: Purchase | F23: Amazon.com | G23: 1 | H23: 0 | I23: 1 | J23: 0.6 | K23: 5.64
... A78: 45992 | B78: Buymeacoffee | C78: Sulima Malzin | D78: Support | E78: Receipt | F78: Buymeacoffee | G78: 1 | H78: 0 | I78: 1 | J78: 1 | K78: 5

Sheet Carolyn
A1: TOTAL SALES
B3: Metrophobia | C3: =SUM(K:K) -> 55.19
B4: Ebook | C4: =SUMIFS(K10:K1000, D10:D1000, "Ebook", E10:E1000, "<>KENP") -> 14.58
B5: Print | C5: =SUMIFS(K10:K1000, D10:D1000, "Paperback") -> 40.5
B6: KENP | C6: =SUMIFS(K10:K1000, D10:D1000, "Ebook", E10:E1000, "KENP") -> 0.11
A10: Date | B10: Title | C10: Author | D10: Format | E10: Type | F10: Marketplace | G10: Units Sold | H10: Units Refunded | I10: Net Units Sold | J10: Payout | K10: Earnings
A11: {=_xlfn._xlws.FILTER(Transactions!A2:K978, Transactions!C2:C978="Carolyn Martin", "No records")} -> 45870 | B11: Metrophobia | C11: Carolyn Martin | D11: Paperback | E11: Purchase | F11: Amazon.com | G11: 1 | H11: 0 | I11: 1 | J11: 0.6 | K11: 12
A12: 45870 | B12: Metrophobia | C12: Carolyn Martin | D12: Ebook | E12: KENP | F12: Amazon.com | G12: 0 | H12: 0 | I12: 0 | J12: 1 | K12: 0.05
A13: 45870 | B13: Metrophobia | C13: Carolyn Martin | D13: Ebook | E13: Pre-order | F13: Amazon.com | G13: 1 | H13: 0 | I13: 1 | J13: 0.7 | K13: 4.86
A14: 45870 | B14: Metrophobia | C14: Carolyn Martin | D14: Paperback | E14: Purchase | F14: Amazon.ca | G14: 1 | H14: 0 | I14: 1 | J14: 0.6 | K14: 6.9
A15: 45870 | B15: Metrophobia | C15: Carolyn Martin | D15: Ebook | E15: Purchase | F15: Amazon.com | G15: 1 | H15: 0 | I15: 1 | J15: 0.7 | K15: 4.86
A16: 45870 | B16: Metrophobia | C16: Carolyn Martin | D16: Paperback | E16: Purchase | F16: Amazon.com | G16: 1 | H16: 0 | I16: 1 | J16: 0.6 | K16: 4.9
A17: 45901 | B17: Metrophobia | C17: Carolyn Martin | D17: Paperback | E17: Purchase | F17: Amazon.com | G17: 1 | H17: 0 | I17: 1 | J17: 0.6 | K17: 4.9
A18: 45931 | B18: Metrophobia | C18: Carolyn Martin | D18: Paperback | E18: Purchase | F18: Amazon.ca | G18: 1 | H18: 0 | I18: 1 | J18: 0.6 | K18: 6.9
A19: 45931 | B19: Metrophobia | C19: Carolyn Martin | D19: Paperback | E19: Purchase | F19: Amazon.com | G19: 1 | H19: 0 | I19: 1 | J19: 0.6 | K19: 4.9
A20: 45962 | B20: Metrophobia | C20: Carolyn Martin | D20: Ebook | E20: KENP | F20: Amazon.com | G20: 0 | H20: 0 | I20: 0 | J20: 1 | K20: 0.06
A21: 45962 | B21: Metrophobia | C21: Carolyn Martin | D21: Ebook | E21: Purchase | F21: Amazon.com | G21: 1 | H21: 0 | I21: 1 | J21: 0.7 | K21: 4.86

Sheet Transactions
A1: Date | B1: Title | C1: Author | D1: Format | E1: Type | F1: Marketplace | G1: Units Sold | H1: Units Refunded | I1: Net Units Sold | J1: Payout | K1: Earnings | L1: KEEP%
A2: 44805 | B2: (multiple) | C2: Sulima Malzin | D2: (multiple) | E2: Payment | F2: (multiple) | K2: 242.51
A3: 44850 | B3: (multiple) | C3: Sulima Malzin | D3: (multiple) | E3: Payment | F3: (multiple) | K3: -40
A4: 44957 | B4: (multiple) | C4: Sulima Malzin | D4: (multiple) | E4: Payment | F4: (multiple) | K4: -29
A5: 45027 | B5: (multiple) | C5: Sulima Malzin | D5: (multiple) | E5: Payment | F5: (multiple) | K5: -29
A6: 45047 | B6: Arms Filled with Bittersweet | C6: Sulima Malzin | D6: Ebook | E6: Pre-order | F6: Amazon.com | G6: 15 | H6: 0 | I6: 15 | J6: 0.35 | K6: 5.25
A7: 45047 | B7: Arms Filled with Bittersweet | C7: Sulima Malzin | D7: Ebook | E7: Free promo | F7: Amazon.com | G7: 55 | H7: 0 | I7: 55 | J7: 0.35 | K7: 0
A8: 45047 | B8: Arms Filled with Bittersweet | C8: Sulima Malzin | D8: Ebook | E8: Free promo | F8: Amazon.com | G8: 1 | H8: 0 | I8: 1 | J8: 0.35 | K8: 0
A9: 45047 | B9: Arms Filled with Bittersweet | C9: Sulima Malzin | D9: Ebook | E9: Free promo | F9: Amazon.co.uk | G9: 2 | H9: 0 | I9: 2 | J9: 0.35 | K9: 0
A10: 45047 | B10: Arms Filled with Bittersweet | C10: Sulima Malzin | D10: Ebook | E10: Free price match | F10: Amazon.ca | G10: 1 | H10: 0 | I10: 1 | J10: 0.35 | K10: 0
A11: 45047 | B11: Arms Filled with Bittersweet | C11: Sulima Malzin | D11: Ebook | E11: Free promo | F11: Amazon.ca | G11: 1 | H11: 0 | I11: 1 | J11: 0.35 | K11: 0
A12: 45047 | B12: Arms Filled with Bittersweet | C12: Sulima Malzin | D12: Ebook | E12: Free promo | F12: Amazon.in | G12: 1 | H12: 0 | I12: 1 | J12: 0.35 | K12: 0
A13: 45047 | B13: Arms Filled with Bittersweet | C13: Sulima Malzin | D13: Paperback | E13: Purchase | F13: Amazon.com | G13: 1 | H13: 0 | I13: 1 | J13: 0.6 | K13: 5.64
A14: 45047 | B14: Arms Filled with Bittersweet | C14: Sulima Malzin | D14: Paperback | E14: Purchase | F14: Amazon.com | G14: 1 | H14: 0 | I14: 1 | J14: 0.6 | K14: 5.64
A15: 45047 | B15: Arms Filled with Bittersweet | C15: Sulima Malzin | D15: Paperback | E15: Purchase | F15: Amazon.com | G15: 1 | H15: 0 | I15: 1 | J15: 0.6 | K15: 5.64
A16: 45047 | B16: Arms Filled with Bittersweet | C16: Sulima Malzin | D16: Paperback | E16: Purchase | F16: Amazon.com | G16: 4 | H16: 0 | I16: 4 | J16: 0.6 | K16: 22.56
A17: 45047 | B17: Arms Filled with Bittersweet | C17: Sulima Malzin | D17: Ebook | E17: KENP | F17: Amazon.com | G17: 27 | H17: 0 | I17: 0 | J17: 0 | K17: 0.118638
... A24: 45139 | B24: Arms Filled with Bittersweet | C24: Sulima Malzin | D24: Ebook | E24: KENP | F24: Amazon.ca | G24: 107 | H24: 0 | I24: 0 | J24: 0 | K24: 0.470158
A25: 45139 | B25: (multiple) | C25: Sulima Malzin | D25: (multiple) | E25: Payment | F25: (multiple) | K25: -45
A26: 45200 | B26: Arms Filled with Bittersweet | C26: Sulima Malzin | D26: Ebook | E26: KENP | F26: Amazon.com | G26: 4 | H26: 0 | I26: 0 | J26: 0 | K26: 0.017576
A27: 45203 | B27: (multiple) | C27: Sulima Malzin | D27: (multiple) | E27: Payment | F27: (multiple) | K27: -22
A28: 45231 | B28: Arms Filled with Bittersweet | C28: Sulima Malzin | D28: Ebook | E28: KENP | F28: Amazon.com | G28: 136 | H28: 0 | I28: 0 | J28: 0 | K28: 0.597584
A29: 45259 | B29: (multiple) | C29: Sulima Malzin | D29: (multiple) | E29: Payment | F29: (multiple) | K29: -16
A30: 45261 | B30: Words That Dance | C30: Sulima Malzin | D30: Paperback | E30: Purchase | F30: Amazon.com | G30: 1 | H30: 0 | I30: 1 | J30: 0.6 | K30: 6.7
A31: 45271 | B31: (multiple) | C31: Sulima Malzin | D31: (multiple) | E31: Payment | F31: (multiple) | K31: -59
A32: 45298 | B32: (multiple) | C32: Sulima Malzin | D32: (multiple) | E32: Payment | F32: (multiple) | K32: -11
A33: 45330 | B33: (multiple) | C33: Sulima Malzin | D33: (multiple) | E33: Payment | F33: (multiple) | K33: -59
A34: 45352 | B34: Words That Dance | C34: Sulima Malzin | D34: Paperback | E34: Purchase | F34: Amazon.com | G34: 1 | H34: 0 | I34: 1 | J34: 0.6 | K34: 6.7
A35: 45383 | B35: Tributaries | C35: Sulima Malzin | D35: Ebook | E35: Pre-order | F35: Amazon.com | G35: 2 | H35: 0 | I35: 2 | J35: 0.35 | K35: 0.7
A36: 45383 | B36: Painting Celia | C36: Maya Bairey | D36: Paperback | E36: Purchase | F36: In person | G36: 1 | H36: 0 | I36: 1 | J36: 1 | K36: 9.48
A37: 45383 | B37: Painting Celia | C37: Maya Bairey | D37: Paperback | E37: Purchase | F37: In person | G37: 1 | H37: 0 | I37: 1 | J37: 1 | K37: 9.48
A38: 45383 | B38: Painting Celia | C38: Maya Bairey | D38: Paperback | E38: Purchase | F38: In person | G38: 1 | H38: 0 | I38: 1 | J38: 1 | K38: 9.48
A39: 45383 | B39: Painting Celia | C39: Maya Bairey | D39: Paperback | E39: Purchase | F39: In person | G39: 1 | H39: 0 | I39: 1 | J39: 1 | K39: 9.48
A40: 45383 | B40: Painting Celia | C40: Maya Bairey | D40: Paperback | E40: Purchase | F40: In person | G40: 1 | H40: 0 | I40: 1 | J40: 1 | K40: 9.48
A41: 45413 | B41: Painting Celia | C41: Maya Bairey | D41: Ebook | E41: Pre-order | F41: Amazon.com | G41: 23 | H41: 0 | I41: 23 | J41: 0.35 | K41: 8.05 | L41: =IFERROR(VLOOKUP(B41, Lists!C:G, 5, FALSE), 0) -> 1
A42: 45413 | B42: Painting Celia | C42: Maya Bairey | D42: Ebook | E42: Goodreads | F42: Amazon.com | G42: 100 | H42: 0 | I42: 100 | J42: 0.35 | K42: 0 | L42: =IFERROR(VLOOKUP(B42, Lists!C:G, 5, FALSE), 0) -> 1
A43: 45413 | B43: Painting Celia | C43: Maya Bairey | D43: Ebook | E43: Free promo | F43: Amazon.com | G43: 304 | H43: 0 | I43: 304 | J43: 0.35 | K43: 0 | L43: =IFERROR(VLOOKUP(B43, Lists!C:G, 5, FALSE), 0) -> 1
A44: 45413 | B44: Painting Celia | C44: Maya Bairey | D44: Ebook | E44: Free promo | F44: Amazon.com | G44: 1 | H44: 0 | I44: 1 | J44: 0.35 | K44: 0 | L44: =IFERROR(VLOOKUP(B44, Lists!C:G, 5, FALSE), 0) -> 1
A45: 45413 | B45: Painting Celia | C45: Maya Bairey | D45: Ebook | E45: Free promo | F45: Amazon.com | G45: 2 | H45: 0 | I45: 2 | J45: 0.35 | K45: 0 | L45: =IFERROR(VLOOKUP(B45, Lists!C:G, 5, FALSE), 0) -> 1
A46: 45413 | B46: Painting Celia | C46: Maya Bairey | D46: Ebook | E46: Purchase | F46: Amazon.com | G46: 96 | H46: 0 | I46: 96 | J46: 0.35 | K46: 33.6 | L46: =IFERROR(VLOOKUP(B46, Lists!C:G, 5, FALSE), 0) -> 1
...

Sheet Transform
A1: Date | B1: Title | C1: Author | D1: ASIN | E1: Type | F1: Marketplace | G1: Units Sold | H1: Units Refunded | I1: Net Units Sold | J1: Payout | K1: Earnings
A2: =Paste!A2 -> 2025-05 | B2: =Paste!B2 -> Painting Celia | C2: =Paste!C2 -> Maya Bairey | D2: =Paste!D2 -> B0D13JKQD6 | E2: =_xlfn.XLOOKUP(Paste!D2, Lists!A:A, Lists!B:B, "Unknown") -> Ebook | F2: =Paste!E2 -> Amazon.com | G2: =Paste!H2 -> 551 | H2: 0 | I2: =IFERROR(VALUE(Paste!J2),0) -> 0 | J2: =Paste!I2 -> N/A | K2: =Paste!P2 -> 2.42
A3: =Paste!A3 -> 2025-05 | B3: =Paste!B3 -> Tributaries | C3: =Paste!C3 -> Sulima Malzin | D3: B0CZ94H5N4 | E3: =_xlfn.XLOOKUP(Paste!D3, Lists!A:A, Lists!B:B, "Unknown") -> Unknown | F3: =Paste!E3 -> Amazon.com | G3: =Paste!H3 -> 1 | H3: =Paste!G3 -> 0 | I3: =IFERROR(VALUE(Paste!J3),0) -> 0 | J3: =Paste!I3 -> 60% | K3: =Paste!P3 -> 3.1
A4: =Paste!A4 -> 2025-05 | B4: =Paste!B4 -> Words That Dance | C4: =Paste!C4 -> Sulima Malzin | D4: B0CPYMRVSV | E4: =_xlfn.XLOOKUP(Paste!D4, Lists!A:A, Lists!B:B, "Unknown") -> Unknown | F4: =Paste!E4 -> Amazon.com | G4: =Paste!H4 -> 1 | H4: =Paste!G4 -> 0 | I4: =IFERROR(VALUE(Paste!J4),0) -> 0 | J4: =Paste!I4 -> 60% | K4: =Paste!P4 -> 4.45
A5: =Paste!A5 -> 2025-05 | B5: =Paste!B5 -> All In The Soup Together | C5: =Paste!C5 -> Sulima Malzin | D5: B0C7J5BMBV | E5: =_xlfn.XLOOKUP(Paste!D5, Lists!A:A, Lists!B:B, "Unknown") -> Unknown | F5: =Paste!E5 -> Amazon.com | G5: =Paste!H5 -> 1 | H5: =Paste!G5 -> 0 | I5: =IFERROR(VALUE(Paste!J5),0) -> 0 | J5: =Paste!I5 -> 60% | K5: =Paste!P5 -> 6.7
A6: =Paste!A6 -> 2025-05 | B6: =Paste!B6 -> Painting Celia | C6: =Paste!C6 -> Maya Bairey | D6: B0CZRWBGHL | E6: =_xlfn.XLOOKUP(Paste!D6, Lists!A:A, Lists!B:B, "Unknown") -> Unknown | F6: =Paste!E6 -> Amazon.it | G6: =Paste!H6 -> 1 | H6: =Paste!G6 -> 0 | I6: =IFERROR(VALUE(Paste!J6),0) -> 0 | J6: =Paste!I6 -> 60% | K6: =Paste!P6 -> 2.79
A7: =Paste!A7 -> 2025-05 | B7: =Paste!B7 -> Painting Celia | C7: =Paste!C7 -> Maya Bairey | D7: =Paste!D7 -> B0D13JKQD6 | E7: =_xlfn.XLOOKUP(Paste!D7, Lists!A:A, Lists!B:B, "Unknown") -> Ebook | F7: =Paste!E7 -> Amazon.com.au | G7: =Paste!H7 -> 1 | H7: =Paste!G7 -> 0 | I7: =IFERROR(VALUE(Paste!J7),0) -> 0 | J7: =Paste!I7 -> 70% | K7: =Paste!P7 -> 2.9
A8: =Paste!A8 -> 2025-06 | B8: =Paste!B8 -> Painting Celia | C8: =Paste!C8 -> Maya Bairey | D8: =Paste!D8 -> B0D13JKQD6 | E8: =_xlfn.XLOOKUP(Paste!D8, Lists!A:A, Lists!B:B, "Unknown") -> Ebook | F8: =Paste!E8 -> Amazon.com | G8: =Paste!H8 -> 1 | H8: =Paste!G8 -> 0 | I8: =IFERROR(VALUE(Paste!J8),0) -> 0 | J8: =Paste!I8 -> 35% | K8: =Paste!P8 -> 1.05
A9: =Paste!A9 -> 2025-06 | B9: =Paste!B9 -> Arms Filled with Bittersweet | C9: =Paste!C9 -> Sulima Malzin | D9: =Paste!D9 -> B0C3S6XSR1 | E9: =_xlfn.XLOOKUP(Paste!D9, Lists!A:A, Lists!B:B, "Unknown") -> Ebook | F9: =Paste!E9 -> Amazon.com | G9: =Paste!H9 -> 1 | H9: 0 | I9: =IFERROR(VALUE(Paste!J9),0) -> 0 | J9: =Paste!I9 -> 70% | K9: =Paste!P9 -> 2.04
A10: =Paste!A10 -> 2025-06 | B10: =Paste!B10 -> Arms Filled with Bittersweet | C10: =Paste!C10 -> Sulima Malzin | D10: =Paste!D10 -> B0C3S6XSR1 | E10: =_xlfn.XLOOKUP(Paste!D10, Lists!A:A, Lists!B:B, "Unknown") -> Ebook | F10: =Paste!E10 -> Amazon.com | G10: =Paste!H10 -> 1 | H10: 0 | I10: =IFERROR(VALUE(Paste!J10),0) -> 0 | J10: =Paste!I10 -> N/A | K10: =Paste!P10 -> 0
A11: =Paste!A11 -> 2025-06 | B11: =Paste!B11 -> Painting Celia | C11: =Paste!C11 -> Maya Bairey | D11: =Paste!D11 -> B0D13JKQD6 | E11: =_xlfn.XLOOKUP(Paste!D11, Lists!A:A, Lists!B:B, "Unknown") -> Ebook | F11: =Paste!E11 -> Amazon.com | G11: =Paste!H11 -> 39 | H11: 0 | I11: =IFERROR(VALUE(Paste!J11),0) -> 0 | J11: =Paste!I11 -> N/A | K11: =Paste!P11 -> 0.17
A12: =Paste!A12 -> 2025-06 | B12: =Paste!B12 -> Painting Celia | C12: =Paste!C12 -> Maya Bairey | D12: =Paste!D12 -> B0D13JKQD6 | E12: =_xlfn.XLOOKUP(Paste!D12, Lists!A:A, Lists!B:B, "Unknown") -> Ebook | F12: =Paste!E12 -> Amazon.ca | G12: =Paste!H12 -> 1 | H12: 0 | I12: =IFERROR(VALUE(Paste!J12),0) -> 0 | J12: =Paste!I12 -> 70% | K12: =Paste!P12 -> 2.83
A13: =Paste!A13 -> 2025-07 | B13: =Paste!B13 -> Painting Celia | C13: =Paste!C13 -> Maya Bairey | D13: =Paste!D13 -> B0D13JKQD6 | E13: =_xlfn.XLOOKUP(Paste!D13, Lists!A:A, Lists!B:B, "Unknown") -> Ebook | F13: =Paste!E13 -> Amazon.com | G13: =Paste!H13 -> 515 | H13: 0 | I13: =IFERROR(VALUE(Paste!J13),0) -> 0 | J13: =Paste!I13 -> N/A | K13: =Paste!P13 -> 2.16
A14: =Paste!A14 -> 2025-07 | B14: =Paste!B14 -> Painting Celia | C14: =Paste!C14 -> Maya Bairey | D14: B0CZRWBGHL | E14: =_xlfn.XLOOKUP(Paste!D14, Lists!A:A, Lists!B:B, "Unknown") -> Unknown | F14: =Paste!E14 -> Amazon.com | G14: =Paste!H14 -> 2 | H14: 0 | I14: =IFERROR(VALUE(Paste!J14),0) -> 0 | J14: =Paste!I14 -> 60% | K14: =Paste!P14 -> 3.1
A15: =Paste!A15 -> 2025-07 | B15: =Paste!B15 -> Painting Celia | C15: =Paste!C15 -> Maya Bairey | D15: =Paste!D15 -> B0D13JKQD6 | E15: =_xlfn.XLOOKUP(Paste!D15, Lists!A:A, Lists!B:B, "Unknown") -> Ebook | F15: =Paste!E15 -> Amazon.com.au | G15: =Paste!H15 -> 108 | H15: 0 | I15: =IFERROR(VALUE(Paste!J15),0) -> 0 | J15: =Paste!I15 -> N/A | K15: =Paste!P15 -> 0.39
A18: Date | B18: Title | C18: Author | D18: ASIN | E18: Type | F18: Marketplace | G18: Units Sold | H18: Units Refunded | I18: Net Units Sold | J18: Payout | K18: Earnings
A19: =A2 -> 2025-05 | B19: =B2 -> Painting Celia | C19: =C2 -> Maya Bairey | D19: =D2 -> B0D13JKQD6 | E19: KENP | F19: =F2 -> Amazon.com | G19: =G2 -> 551 | H19: =H2 -> 0 | I19: =Paste!J81 -> 0 | J19: =K2 -> 2.42 | K19: =J19 -> 2.42
A20: =A11 -> 2025-06 | B20: =B11 -> Painting Celia | C20: =C11 -> Maya Bairey | D20: =D11 -> B0D13JKQD6 | E20: KENP | F20: =F11 -> Amazon.com | G20: =G11 -> 39 | H20: =H11 -> 0 | I20: =Paste!J90 -> 0 | J20: =K11 -> 0.17 | K20: =J20 -> 0.17
A21: =A13 -> 2025-07 | B21: =B13 -> Painting Celia | C21: =C13 -> Maya Bairey | D21: =D13 -> B0D13JKQD6 | E21: KENP | F21: =F13 -> Amazon.com | G21: =G13 -> 515 | H21: =H13 -> 0 | I21: =Paste!J92 -> 0 | J21: =K13 -> 2.16 | K21: =J21 -> 2.16
A22: =A15 -> 2025-07 | B22: =B15 -> Painting Celia | C22: =C15 -> Maya Bairey | D22: =D15 -> B0D13JKQD6 | E22: KENP | F22: =F15 -> Amazon.com.au | G22: =G15 -> 108 | H22: =H15 -> 0 | I22: =Paste!J94 -> 0 | J22: =K15 -> 0.39 | K22: =J22 -> 0.39

Sheet Paste
A1: MONTH | B1: Title | C1: Author | D1: ASIN/ISBN | E1: Marketplace | F1: Units Sold | G1: Units Refunded | H1: Net Units Sold or Combined KENP | I1: Royalty Type | J1: Payout Plan | K1: Currency | L1: Avg. List Price without tax | M1: Avg. Offer Price without tax | N1: Avg. File Size (MB) | O1: Avg. Delivery/Manufacturing cost | P1: Earnings
A2: 2025-05 | B2: Painting Celia | C2: Maya Bairey | D2: B0D13JKQD6 | E2: Amazon.com | F2: N/A | G2: N/A | H2: 551 | I2: N/A | J2: Kindle Edition Normalized Pages (KENP) | K2: USD | L2: N/A | M2: N/A | N2: N/A | O2: N/A | P2: 2.42
A3: 2025-05 | B3: Tributaries | C3: Sulima Malzin | D3: 9798990065598 | E3: Amazon.com | F3: 1 | G3: 0 | H3: 1 | I3: 60% | J3: Standard - Paperback | K3: USD | L3: 9 | M3: 9 | N3: N/A | O3: 2.3 | P3: 3.1
A4: 2025-05 | B4: Words That Dance | C4: Sulima Malzin | D4: 9798871161425 | E4: Amazon.com | F4: 1 | G4: 0 | H4: 1 | I4: 60% | J4: Standard - Paperback | K4: USD | L4: 11.25 | M4: 11.25 | N4: N/A | O4: 2.3 | P4: 4.45
A5: 2025-05 | B5: All In The Soup Together | C5: Sulima Malzin | D5: 9798397667593 | E5: Amazon.com | F5: 1 | G5: 0 | H5: 1 | I5: 60% | J5: Standard - Paperback | K5: USD | L5: 15 | M5: 15 | N5: N/A | O5: 2.3 | P5: 6.7
A6: 2025-05 | B6: Painting Celia | C6: Maya Bairey | D6: 9798990065550 | E6: Amazon.it | F6: 1 | G6: 0 | H6: 1 | I6: 60% | J6: Standard - Paperback | K6: EUR | L6: 12.37 | M6: 12.37 | N6: N/A | O6: 4.63 | P6: 2.79
A7: 2025-05 | B7: Painting Celia | C7: Maya Bairey | D7: B0D13JKQD6 | E7: Amazon.com.au | F7: 1 | G7: 0 | H7: 1 | I7: 70% | J7: Standard | K7: AUD | L7: 4.25 | M7: 4.25 | N7: 0.67 | O7: 0.1 | P7: 2.9
A8: 2025-06 | B8: Painting Celia | C8: Maya Bairey | D8: B0D13JKQD6 | E8: Amazon.com | F8: 1 | G8: 0 | H8: 1 | I8: 35% | J8: Standard | K8: USD | L8: 2.99 | M8: 2.99 | N8: 0.67 | O8: N/A | P8: 1.05
A9: 2025-06 | B9: Arms Filled with Bittersweet | C9: Sulima Malzin | D9: B0C3S6XSR1 | E9: Amazon.com | F9: 1 | G9: 0 | H9: 1 | I9: 70% | J9: Standard | K9: USD | L9: 2.99 | M9: 2.99 | N9: 0.5 | O9: 0.07 | P9: 2.04
A10: 2025-06 | B10: Arms Filled with Bittersweet | C10: Sulima Malzin | D10: B0C3S6XSR1 | E10: Amazon.com | F10: N/A | G10: N/A | H10: 1 | I10: N/A | J10: Kindle Edition Normalized Pages (KENP) | K10: USD | L10: N/A | M10: N/A | N10: N/A | O10: N/A | P10: 0
A11: 2025-06 | B11: Painting Celia | C11: Maya Bairey | D11: B0D13JKQD6 | E11: Amazon.com | F11: N/A | G11: N/A | H11: 39 | I11: N/A | J11: Kindle Edition Normalized Pages (KENP) | K11: USD | L11: N/A | M11: N/A | N11: N/A | O11: N/A | P11: 0.17
A12: 2025-06 | B12: Painting Celia | C12: Maya Bairey | D12: B0D13JKQD6 | E12: Amazon.ca | F12: 1 | G12: 0 | H12: 1 | I12: 70% | J12: Standard | K12: CAD | L12: 4.14 | M12: 4.14 | N12: 0.67 | O12: 0.1 | P12: 2.83
A13: 2025-07 | B13: Painting Celia | C13: Maya Bairey | D13: B0D13JKQD6 | E13: Amazon.com | F13: N/A | G13: N/A | H13: 515 | I13: N/A | J13: Kindle Edition Normalized Pages (KENP) | K13: USD | L13: N/A | M13: N/A | N13: N/A | O13: N/A | P13: 2.16
A14: 2025-07 | B14: Painting Celia | C14: Maya Bairey | D14: 9798990674905 | E14: Amazon.com | F14: 2 | G14: 0 | H14: 2 | I14: 60% | J14: Standard - Hardcover | K14: USD | L14: 16.99 | M14: 16.99 | N14: N/A | O14: 8.64 | P14: 3.1
A15: 2025-07 | B15: Painting Celia | C15: Maya Bairey | D15: B0D13JKQD6 | E15: Amazon.com.au | F15: N/A | G15: N/A | H15: 108 | I15: N/A | J15: Kindle Edition Normalized Pages (KENP) | K15: AUD | L15: N/A | M15: N/A | N15: N/A | O15: N/A | P15: 0.39
A79: KENP
A80: Date | B80: Title | C80: Author Name | D80: eBook ASIN | E80: Audiobook ASIN | F80: Audible ASIN | G80: Marketplace | H80: KENP | I80: Returns | J80: Royalty | K80: KENP PAID
A81: 45770 | B81: Painting Celia | C81: Maya Bairey | D81: B0D13JKQD6 | E81: N/A | F81: N/A | G81: Amazon.com | H81: 7 | I81: 0 | J81: 0 | K81: =H81*0.00475 -> 0.03325
A82: 45768 | B82: Painting Celia | C82: Maya Bairey | D82: B0D13JKQD6 | E82: N/A | F82: N/A | G82: Amazon.com | H82: 1 | I82: 0 | J82: 0 | K82: =H82*0.00475 -> 0.00475
A83: 45767 | B83: Painting Celia | C83: Maya Bairey | D83: B0D13JKQD6 | E83: N/A | F83: N/A | G83: Amazon.com | H83: 2 | I83: 0 | J83: 0 | K83: =H83*0.00475 -> 0.0095
A84: 45765 | B84: Painting Celia | C84: Maya Bairey | D84: B0D13JKQD6 | E84: N/A | F84: N/A | G84: Amazon.com | H84: 19 | I84: 0 | J84: 0 | K84: =H84*0.00475 -> 0.09025
A85: 45764 | B85: Painting Celia | C85: Maya Bairey | D85: B0D13JKQD6 | E85: N/A | F85: N/A | G85: Amazon.com | H85: 38 | I85: 0 | J85: 0 | K85: =H85*0.00475 -> 0.1805
A86: 45763 | B86: Painting Celia | C86: Maya Bairey | D86: B0D13JKQD6 | E86: N/A | F86: N/A | G86: Amazon.com | H86: 1 | I86: 0 | J86: 0 | K86: =H86*0.00475 -> 0.00475
A87: 45761 | B87: Painting Celia | C87: Maya Bairey | D87: B0D13JKQD6 | E87: N/A | F87: N/A | G87: Amazon.com | H87: 81 | I87: 0 | J87: 0 | K87: =H87*0.00475 -> 0.38475
A88: 45760 | B88: Painting Celia | C88: Maya Bairey | D88: B0D13JKQD6 | E88: N/A | F88: N/A | G88: Amazon.com | H88: 1 | I88: 0 | J88: 0 | K88: =H88*0.00475 -> 0.00475
A89: 45755 | B89: Painting Celia | C89: Maya Bairey | D89: B0D13JKQD6 | E89: N/A | F89: N/A | G89: Amazon.com | H89: 41 | I89: 0 | J89: 0 | K89: =H89*0.00475 -> 0.19475
A90: 45752 | B90: Painting Celia | C90: Maya Bairey | D90: B0D13JKQD6 | E90: N/A | F90: N/A | G90: Amazon.com | H90: 249 | I90: 0 | J90: 0 | K90: =H90*0.00475 -> 1.18275
A91: 45751 | B91: Painting Celia | C91: Maya Bairey | D91: B0D13JKQD6 | E91: N/A | F91: N/A | G91: Amazon.com | H91: 106 | I91: 0 | J91: 0 | K91: =H91*0.00475 -> 0.5035
A92: 45750 | B92: Painting Celia | C92: Maya Bairey | D92: B0D13JKQD6 | E92: N/A | F92: N/A | G92: Amazon.com | H92: 5 | I92: 0 | J92: 0 | K92: =H92*0.00475 -> 0.02375
A93: 45748 | B93: Painting Celia | C93: Maya Bairey | D93: B0D13JKQD6 | E93: N/A | F93: N/A | G93: Amazon.ca | H93: 39 | I93: 0 | J93: 0 | K93: =H93*0.00475 -> 0.18525

Sheet Lists
A1: ASIN | B1: Type | C1: Title | D1: Author | E1: ISBN | F1: Last Price | G1: Keep | I1: Purchase type | L1: Authors | N1: Start | O1: End
A2: B0D13JKQD6 | B2: Ebook | C2: Painting Celia | D2: Maya Bairey | E2: 979-8-9900655-6-7 | F2: 2.99 | G2: 1 | I2: Standard | J2: Purchase | L2: Maya Bairey | N2: 45992 | O2: 46022
A3: B0CZRWBGHL | B3: Paperback | C3: Painting Celia | D3: Maya Bairey | E3: 979-8-9900655-5-0 | F3: 9.99 | G3: 1 | I3: Kindle Edition Normalized Pages (KENP) | J3: KENP | L3: Sulima Malzin | N3: 45962 | O3: 45991
A4: B0D33MQ4F5 | B4: Hard cover | C4: Painting Celia | D4: Maya Bairey | E4: 979-8-9906749-0-5 | F4: 16.99 | G4: 1 | I4: Free - Promotion | J4: Free promo | L4: Carolyn Martin | N4: 45931 | O4: 45961
A5: B0C3S6XSR1 | B5: Ebook | C5: Arms Filled with Bittersweet | D5: Sulima Malzin | E5: 979-8-9900655-2-9 | F5: 2.99 | G5: 0 | I5: Standard - Paperback | J5: Purchase | N5: 45901 | O5: 45930
A6: B0C2S7MKKD | B6: Paperback | C6: Arms Filled with Bittersweet | D6: Sulima Malzin | E6: 979-8-9900655-1-2 | F6: 12.75 | G6: 0 | I6: Free - Goodreads Giveaway | J6: Goodreads | N6: 45870 | O6: 45900
A7: B0C7JWZ625 | B7: Ebook | C7: All In The Soup Together | D7: Sulima Malzin | E7: 979-8-9900655-4-3 | F7: 2.99 | G7: 0 | I7: Pre Order | J7: Pre-order | N7: 45839 | O7: 45869
A8: B0C7J5BMBV | B8: Paperback | C8: All In The Soup Together | D8: Sulima Malzin | E8: 979-8-9900655-3-6 | F8: 15 | G8: 0 | I8: Free - Price Match | J8: Free price match | N8: 45809 | O8: 45838
A9: B0CPYMRVSV | B9: Paperback | C9: Words That Dance | D9: Sulima Malzin | E9: 979-8-9900655-0-5 | F9: 11.25 | G9: 0 | N9: 45778 | O9: 45808
A10: B0CYZTSXMN | B10: Ebook | C10: Tributaries | D10: Sulima Malzin | E10: 979-8-9900655-9-8 | F10: 0.99 | G10: 0 | N10: 45748 | O10: 45777
A11: B0CZ94H5N4 | B11: Paperback | C11: Tributaries | D11: Sulima Malzin | E11: 979-8-9900655-9-8 | F11: 9 | G11: 0 | N11: 45717 | O11: 45747
A12: B0FF88MYC6 | B12: Paperback | C12: Metrophobia | D12: Carolyn Martin | E12: 979-8-9906749-1-2 | F12: 12 | G12: 0.5 | N12: 45689 | O12: 45716
A13: B0FF3BCH52 | B13: Ebook | C13: Metrophobia | D13: Carolyn Martin | E13: 979-8-9906749-2-9 | F13: 2.99 | G13: 0.5 | N13: 45658 | O13: 45688
N14: 45627 | O14: 45657
N15: 45597 | O15: 45626
N16: 45566 | O16: 45596
N17: 45536 | O17: 45565
N18: 45505 | O18: 45535
N19: 45474 | O19: 45504
N20: 45444 | O20: 45473
N21: 45413 | O21: 45443
N22: 45383 | O22: 45412
N23: 45352 | O23: 45382
N24: 45323 | O24: 45351
N25: 45292 | O25: 45322
... N40: 44835 | O40: 44865
