Workbook

Sheet MAYA
A1: [MAYA] | B1: =A2 -> Painting-Celia | C1: =A3 -> Untitled-Kelsey | D1: =A4 -> Sailor's-Code | E1: Source | F1: Asset | G1: Copy | H1: Design | I1: Marketing | J1: Newsletter | K1: Inspo | L1: Admin | M1: Cover | N1: Info | O1: Backup | P1: Headshot | Q1: Interior | R1: OLD | S1: Video | T1: PSD | U1: B-Roll | V1: Featured-image | W1: Social-image
A2: Painting-Celia | B2: 1HYgKE8KHG3aHa5yssRP5QkYSCkixs6Iv | C2: 1ykOtB1Lzao_-YY5kILRep2J-yduW-yvd | D2: 1ykOtB1Lzao_-YY5kILRep2J-yduW-yvd | E2: 121Q8rdnvAjNHDkawLfHg1IAV8Ay02DxJ | F2: 1HYgKE8KHG3aHa5yssRP5QkYSCkixs6Iv | G2: 1HYgKE8KHG3aHa5yssRP5QkYSCkixs6Iv | H2: 1HYgKE8KHG3aHa5yssRP5QkYSCkixs6Iv | I2: 1liZVn5ML72uIAoAhHkp-gcvV2PUbMxIC | J2: 1Ge-0kbMlbbq3Mm6u9ueKITY5H0oFxbXU | K2: 1HYgKE8KHG3aHa5yssRP5QkYSCkixs6Iv | L2: 1Uzt32vdzpwWtCvlMdeebxtAKYtcWjuqg | M2: 1HYgKE8KHG3aHa5yssRP5QkYSCkixs6Iv | N2: 1HYgKE8KHG3aHa5yssRP5QkYSCkixs6Iv | O2: 1FPVSF11YWp7DV9SCG-6uUx43KYfhn84i | P2: 1zeczUMlzYUAQv6t1ZFF7jlnsLiPswUow | Q2: 1HYgKE8KHG3aHa5yssRP5QkYSCkixs6Iv | R2: 1FPVSF11YWp7DV9SCG-6uUx43KYfhn84i | S2: 19dJbRq6GVwGrt9mZJ3NegsuriQ7G57vt | T2: 1epreGeMwReI4rZGEjathYmZXj34jDL67 | U2: 1HYgKE8KHG3aHa5yssRP5QkYSCkixs6Iv | V2: 1R-P27joAfrXZ_BAAoXefChIegp_RFoFW | W2: 1qUXWXlXls6AuziR3mRgM2QESSlalhpSF
A3: Untitled-Kelsey | B3: 1ykOtB1Lzao_-YY5kILRep2J-yduW-yvd | C3: 1RTlmvtOz279OOwW6rzsKi07hzWmbIFdE | D3: 1ykOtB1Lzao_-YY5kILRep2J-yduW-yvd | E3: 121Q8rdnvAjNHDkawLfHg1IAV8Ay02DxJ | F3: 1RTlmvtOz279OOwW6rzsKi07hzWmbIFdE | G3: 1RTlmvtOz279OOwW6rzsKi07hzWmbIFdE | H3: 1RTlmvtOz279OOwW6rzsKi07hzWmbIFdE | I3: 1liZVn5ML72uIAoAhHkp-gcvV2PUbMxIC | J3: 1Ge-0kbMlbbq3Mm6u9ueKITY5H0oFxbXU | K3: 1RTlmvtOz279OOwW6rzsKi07hzWmbIFdE | L3: 1Uzt32vdzpwWtCvlMdeebxtAKYtcWjuqg | M3: 1RTlmvtOz279OOwW6rzsKi07hzWmbIFdE | N3: 1RTlmvtOz279OOwW6rzsKi07hzWmbIFdE | O3: 1FPVSF11YWp7DV9SCG-6uUx43KYfhn84i | P3: 1zeczUMlzYUAQv6t1ZFF7jlnsLiPswUow | Q3: 1RTlmvtOz279OOwW6rzsKi07hzWmbIFdE | R3: 1FPVSF11YWp7DV9SCG-6uUx43KYfhn84i | S3: 19dJbRq6GVwGrt9mZJ3NegsuriQ7G57vt | T3: 1epreGeMwReI4rZGEjathYmZXj34jDL67 | U3: 1HYgKE8KHG3aHa5yssRP5QkYSCkixs6Iv | V3: 1R-P27joAfrXZ_BAAoXefChIegp_RFoFW | W3: 1qUXWXlXls6AuziR3mRgM2QESSlalhpSF
A4: Sailor's-Code | B4: 1ykOtB1Lzao_-YY5kILRep2J-yduW-yvd | C4: 1ykOtB1Lzao_-YY5kILRep2J-yduW-yvd | D4: 1tZYdQCEeHiMObOUF-vn2Zx_IAgH-pQe2 | E4: 121Q8rdnvAjNHDkawLfHg1IAV8Ay02DxJ | F4: 1tZYdQCEeHiMObOUF-vn2Zx_IAgH-pQe2 | G4: 1tZYdQCEeHiMObOUF-vn2Zx_IAgH-pQe2 | H4: 1tZYdQCEeHiMObOUF-vn2Zx_IAgH-pQe2 | I4: 1liZVn5ML72uIAoAhHkp-gcvV2PUbMxIC | J4: 1Ge-0kbMlbbq3Mm6u9ueKITY5H0oFxbXU | K4: 1tZYdQCEeHiMObOUF-vn2Zx_IAgH-pQe2 | L4: 1Uzt32vdzpwWtCvlMdeebxtAKYtcWjuqg | M4: 1tZYdQCEeHiMObOUF-vn2Zx_IAgH-pQe2 | N4: 1tZYdQCEeHiMObOUF-vn2Zx_IAgH-pQe2 | O4: 1FPVSF11YWp7DV9SCG-6uUx43KYfhn84i | P4: 1zeczUMlzYUAQv6t1ZFF7jlnsLiPswUow | Q4: 1tZYdQCEeHiMObOUF-vn2Zx_IAgH-pQe2 | R4: 1FPVSF11YWp7DV9SCG-6uUx43KYfhn84i | S4: 19dJbRq6GVwGrt9mZJ3NegsuriQ7G57vt | T4: 1epreGeMwReI4rZGEjathYmZXj34jDL67 | U4: 1HYgKE8KHG3aHa5yssRP5QkYSCkixs6Iv | V4: 1R-P27joAfrXZ_BAAoXefChIegp_RFoFW | W4: 1qUXWXlXls6AuziR3mRgM2QESSlalhpSF
A5: Source | B5: 121Q8rdnvAjNHDkawLfHg1IAV8Ay02DxJ | C5: 121Q8rdnvAjNHDkawLfHg1IAV8Ay02DxJ | D5: 121Q8rdnvAjNHDkawLfHg1IAV8Ay02DxJ | E5: 121Q8rdnvAjNHDkawLfHg1IAV8Ay02DxJ | F5: 121Q8rdnvAjNHDkawLfHg1IAV8Ay02DxJ | G5: 121Q8rdnvAjNHDkawLfHg1IAV8Ay02DxJ | H5: 121Q8rdnvAjNHDkawLfHg1IAV8Ay02DxJ | I5: 121Q8rdnvAjNHDkawLfHg1IAV8Ay02DxJ | J5: 121Q8rdnvAjNHDkawLfHg1IAV8Ay02DxJ | K5: 121Q8rdnvAjNHDkawLfHg1IAV8Ay02DxJ | L5: 121Q8rdnvAjNHDkawLfHg1IAV8Ay02DxJ | M5: 121Q8rdnvAjNHDkawLfHg1IAV8Ay02DxJ | N5: 121Q8rdnvAjNHDkawLfHg1IAV8Ay02DxJ | O5: 1FPVSF11YWp7DV9SCG-6uUx43KYfhn84i | P5: 121Q8rdnvAjNHDkawLfHg1IAV8Ay02DxJ | Q5: 121Q8rdnvAjNHDkawLfHg1IAV8Ay02DxJ | R5: 1FPVSF11YWp7DV9SCG-6uUx43KYfhn84i | S5: 121Q8rdnvAjNHDkawLfHg1IAV8Ay02DxJ | T5: 121Q8rdnvAjNHDkawLfHg1IAV8Ay02DxJ | U5: 1HYgKE8KHG3aHa5yssRP5QkYSCkixs6Iv | V5: 1R-P27joAfrXZ_BAAoXefChIegp_RFoFW | W5: 1qUXWXlXls6AuziR3mRgM2QESSlalhpSF
A6: Asset | B6: 1HYgKE8KHG3aHa5yssRP5QkYSCkixs6Iv | C6: 1RTlmvtOz279OOwW6rzsKi07hzWmbIFdE | D6: 1tZYdQCEeHiMObOUF-vn2Zx_IAgH-pQe2 | E6: 121Q8rdnvAjNHDkawLfHg1IAV8Ay02DxJ | F6: 1I8Dez0rhnfK1BdJs4O_7ZALuUN5bIurm | G6: 1ykOtB1Lzao_-YY5kILRep2J-yduW-yvd | H6: 1ykOtB1Lzao_-YY5kILRep2J-yduW-yvd | I6: 1liZVn5ML72uIAoAhHkp-gcvV2PUbMxIC | J6: 1Ge-0kbMlbbq3Mm6u9ueKITY5H0oFxbXU | K6: 1ykOtB1Lzao_-YY5kILRep2J-yduW-yvd | L6: 1Uzt32vdzpwWtCvlMdeebxtAKYtcWjuqg | M6: 1ykOtB1Lzao_-YY5kILRep2J-yduW-yvd | N6: 1ykOtB1Lzao_-YY5kILRep2J-yduW-yvd | O6: 1FPVSF11YWp7DV9SCG-6uUx43KYfhn84i | P6: 1zeczUMlzYUAQv6t1ZFF7jlnsLiPswUow | Q6: 1ykOtB1Lzao_-YY5kILRep2J-yduW-yvd | R6: 1FPVSF11YWp7DV9SCG-6uUx43KYfhn84i | S6: 19dJbRq6GVwGrt9mZJ3NegsuriQ7G57vt | T6: 1epreGeMwReI4rZGEjathYmZXj34jDL67 | U6: 19dJbRq6GVwGrt9mZJ3NegsuriQ7G57vt | V6: 1R-P27joAfrXZ_BAAoXefChIegp_RFoFW | W6: 1qUXWXlXls6AuziR3mRgM2QESSlalhpSF
A7: Copy | B7: 1HYgKE8KHG3aHa5yssRP5QkYSCkixs6Iv | C7: 1RTlmvtOz279OOwW6rzsKi07hzWmbIFdE | D7: 1tZYdQCEeHiMObOUF-vn2Zx_IAgH-pQe2 | E7: 121Q8rdnvAjNHDkawLfHg1IAV8Ay02DxJ | F7: 1ykOtB1Lzao_-YY5kILRep2J-yduW-yvd | G7: 1jxC5-kXTYEthBsr18OtKpgTbs3XTKHfV | H7: 1ykOtB1Lzao_-YY5kILRep2J-yduW-yvd | I7: 1liZVn5ML72uIAoAhHkp-gcvV2PUbMxIC | J7: 1Ge-0kbMlbbq3Mm6u9ueKITY5H0oFxbXU | K7: 1ykOtB1Lzao_-YY5kILRep2J-yduW-yvd | L7: 1Uzt32vdzpwWtCvlMdeebxtAKYtcWjuqg | M7: 1ykOtB1Lzao_-YY5kILRep2J-yduW-yvd | N7: 1ykOtB1Lzao_-YY5kILRep2J-yduW-yvd | O7: 1FPVSF11YWp7DV9SCG-6uUx43KYfhn84i | P7: 1zeczUMlzYUAQv6t1ZFF7jlnsLiPswUow | Q7: 1ykOtB1Lzao_-YY5kILRep2J-yduW-yvd | R7: 1FPVSF11YWp7DV9SCG-6uUx43KYfhn84i | S7: 19dJbRq6GVwGrt9mZJ3NegsuriQ7G57vt | T7: 1epreGeMwReI4rZGEjathYmZXj34jDL67 | U7: 1HYgKE8KHG3aHa5yssRP5QkYSCkixs6Iv | V7: 1R-P27joAfrXZ_BAAoXefChIegp_RFoFW | W7: 1qUXWXlXls6AuziR3mRgM2QESSlalhpSF
A8: Design | B8: 1HYgKE8KHG3aHa5yssRP5QkYSCkixs6Iv | C8: 1RTlmvtOz279OOwW6rzsKi07hzWmbIFdE | D8: 1tZYdQCEeHiMObOUF-vn2Zx_IAgH-pQe2 | E8: 121Q8rdnvAjNHDkawLfHg1IAV8Ay02DxJ | F8: 1ykOtB1Lzao_-YY5kILRep2J-yduW-yvd | G8: 1ykOtB1Lzao_-YY5kILRep2J-yduW-yvd | H8: 1R6_DoZSY0HqNG3atkRihKyjnXlXM-qLn | I8: 1liZVn5ML72uIAoAhHkp-gcvV2PUbMxIC | J8: 1Ge-0kbMlbbq3Mm6u9ueKITY5H0oFxbXU | K8: 1ykOtB1Lzao_-YY5kILRep2J-yduW-yvd | L8: 1Uzt32vdzpwWtCvlMdeebxtAKYtcWjuqg | M8: 1ykOtB1Lzao_-YY5kILRep2J-yduW-yvd | N8: 1ykOtB1Lzao_-YY5kILRep2J-yduW-yvd | O8: 1FPVSF11YWp7DV9SCG-6uUx43KYfhn84i | P8: 1zeczUMlzYUAQv6t1ZFF7jlnsLiPswUow | Q8: 1ykOtB1Lzao_-YY5kILRep2J-yduW-yvd | R8: 1FPVSF11YWp7DV9SCG-6uUx43KYfhn84i | S8: 19dJbRq6GVwGrt9mZJ3NegsuriQ7G57vt | T8: 1epreGeMwReI4rZGEjathYmZXj34jDL67 | U8: 1HYgKE8KHG3aHa5yssRP5QkYSCkixs6Iv | V8: 1R-P27joAfrXZ_BAAoXefChIegp_RFoFW | W8: 1qUXWXlXls6AuziR3mRgM2QESSlalhpSF
A9: Marketing | B9: 1liZVn5ML72uIAoAhHkp-gcvV2PUbMxIC | C9: 1liZVn5ML72uIAoAhHkp-gcvV2PUbMxIC | D9: 1liZVn5ML72uIAoAhHkp-gcvV2PUbMxIC | E9: 121Q8rdnvAjNHDkawLfHg1IAV8Ay02DxJ | F9: 1liZVn5ML72uIAoAhHkp-gcvV2PUbMxIC | G9: 1liZVn5ML72uIAoAhHkp-gcvV2PUbMxIC | H9: 1liZVn5ML72uIAoAhHkp-gcvV2PUbMxIC | I9: 1liZVn5ML72uIAoAhHkp-gcvV2PUbMxIC | J9: 1Ge-0kbMlbbq3Mm6u9ueKITY5H0oFxbXU | K9: 1liZVn5ML72uIAoAhHkp-gcvV2PUbMxIC | L9: 1Uzt32vdzpwWtCvlMdeebxtAKYtcWjuqg | M9: 1liZVn5ML72uIAoAhHkp-gcvV2PUbMxIC | N9: 1liZVn5ML72uIAoAhHkp-gcvV2PUbMxIC | O9: 1FPVSF11YWp7DV9SCG-6uUx43KYfhn84i | P9: 1zeczUMlzYUAQv6t1ZFF7jlnsLiPswUow | Q9: 1liZVn5ML72uIAoAhHkp-gcvV2PUbMxIC | R9: 1FPVSF11YWp7DV9SCG-6uUx43KYfhn84i | S9: 19dJbRq6GVwGrt9mZJ3NegsuriQ7G57vt | T9: 1epreGeMwReI4rZGEjathYmZXj34jDL67 | U9: 19dJbRq6GVwGrt9mZJ3NegsuriQ7G57vt | V9: 1R-P27joAfrXZ_BAAoXefChIegp_RFoFW | W9: 1qUXWXlXls6AuziR3mRgM2QESSlalhpSF
A10: Newsletter | B10: 1Ge-0kbMlbbq3Mm6u9ueKITY5H0oFxbXU | C10: 1Ge-0kbMlbbq3Mm6u9ueKITY5H0oFxbXU | D10: 1Ge-0kbMlbbq3Mm6u9ueKITY5H0oFxbXU | E10: 121Q8rdnvAjNHDkawLfHg1IAV8Ay02DxJ | F10: 1Ge-0kbMlbbq3Mm6u9ueKITY5H0oFxbXU | G10: 1Ge-0kbMlbbq3Mm6u9ueKITY5H0oFxbXU | H10: 1Ge-0kbMlbbq3Mm6u9ueKITY5H0oFxbXU | I10: 1Ge-0kbMlbbq3Mm6u9ueKITY5H0oFxbXU | J10: 1Ge-0kbMlbbq3Mm6u9ueKITY5H0oFxbXU | K10: 1Ge-0kbMlbbq3Mm6u9ueKITY5H0oFxbXU | L10: 1Uzt32vdzpwWtCvlMdeebxtAKYtcWjuqg | M10: 1Ge-0kbMlbbq3Mm6u9ueKITY5H0oFxbXU | N10: 1Ge-0kbMlbbq3Mm6u9ueKITY5H0oFxbXU | O10: 1FPVSF11YWp7DV9SCG-6uUx43KYfhn84i | P10: 1zeczUMlzYUAQv6t1ZFF7jlnsLiPswUow | Q10: 1Ge-0kbMlbbq3Mm6u9ueKITY5H0oFxbXU | R10: 1FPVSF11YWp7DV9SCG-6uUx43KYfhn84i | S10: 19dJbRq6GVwGrt9mZJ3NegsuriQ7G57vt | T10: 1epreGeMwReI4rZGEjathYmZXj34jDL67 | U10: 1HYgKE8KHG3aHa5yssRP5QkYSCkixs6Iv | V10: 1Ge-0kbMlbbq3Mm6u9ueKITY5H0oFxbXU | W10: 1qUXWXlXls6AuziR3mRgM2QESSlalhpSF
A11: Inspo | B11: 1HYgKE8KHG3aHa5yssRP5QkYSCkixs6Iv | C11: 1RTlmvtOz279OOwW6rzsKi07hzWmbIFdE | D11: 1tZYdQCEeHiMObOUF-vn2Zx_IAgH-pQe2 | E11: 121Q8rdnvAjNHDkawLfHg1IAV8Ay02DxJ | F11: 1ykOtB1Lzao_-YY5kILRep2J-yduW-yvd | G11: 1ykOtB1Lzao_-YY5kILRep2J-yduW-yvd | H11: 1ykOtB1Lzao_-YY5kILRep2J-yduW-yvd | I11: 1liZVn5ML72uIAoAhHkp-gcvV2PUbMxIC | J11: 1Ge-0kbMlbbq3Mm6u9ueKITY5H0oFxbXU | K11: 1ykOtB1Lzao_-YY5kILRep2J-yduW-yvd | L11: 1Uzt32vdzpwWtCvlMdeebxtAKYtcWjuqg | M11: 1ykOtB1Lzao_-YY5kILRep2J-yduW-yvd | N11: 1ykOtB1Lzao_-YY5kILRep2J-yduW-yvd | O11: 1FPVSF11YWp7DV9SCG-6uUx43KYfhn84i | P11: 1zeczUMlzYUAQv6t1ZFF7jlnsLiPswUow | Q11: 1ykOtB1Lzao_-YY5kILRep2J-yduW-yvd | R11: 1FPVSF11YWp7DV9SCG-6uUx43KYfhn84i | S11: 19dJbRq6GVwGrt9mZJ3NegsuriQ7G57vt | T11: 1epreGeMwReI4rZGEjathYmZXj34jDL67 | U11: 1HYgKE8KHG3aHa5yssRP5QkYSCkixs6Iv | V11: 1R-P27joAfrXZ_BAAoXefChIegp_RFoFW | W11: 1qUXWXlXls6AuziR3mRgM2QESSlalhpSF
A12: Admin | B12: 1Uzt32vdzpwWtCvlMdeebxtAKYtcWjuqg | C12: 1Uzt32vdzpwWtCvlMdeebxtAKYtcWjuqg | D12: 1Uzt32vdzpwWtCvlMdeebxtAKYtcWjuqg | E12: 121Q8rdnvAjNHDkawLfHg1IAV8Ay02DxJ | F12: 1Uzt32vdzpwWtCvlMdeebxtAKYtcWjuqg | G12: 1Uzt32vdzpwWtCvlMdeebxtAKYtcWjuqg | H12: 1Uzt32vdzpwWtCvlMdeebxtAKYtcWjuqg | I12: 1Uzt32vdzpwWtCvlMdeebxtAKYtcWjuqg | J12: 1Uzt32vdzpwWtCvlMdeebxtAKYtcWjuqg | K12: 1Uzt32vdzpwWtCvlMdeebxtAKYtcWjuqg | L12: 1Uzt32vdzpwWtCvlMdeebxtAKYtcWjuqg | M12: 1Uzt32vdzpwWtCvlMdeebxtAKYtcWjuqg | N12: 1Uzt32vdzpwWtCvlMdeebxtAKYtcWjuqg | O12: 1FPVSF11YWp7DV9SCG-6uUx43KYfhn84i | P12: 1Uzt32vdzpwWtCvlMdeebxtAKYtcWjuqg | Q12: 1Uzt32vdzpwWtCvlMdeebxtAKYtcWjuqg | R12: 1FPVSF11YWp7DV9SCG-6uUx43KYfhn84i | S12: 1Uzt32vdzpwWtCvlMdeebxtAKYtcWjuqg | T12: 1epreGeMwReI4rZGEjathYmZXj34jDL67 | U12: 1Uzt32vdzpwWtCvlMdeebxtAKYtcWjuqg | V12: 1Uzt32vdzpwWtCvlMdeebxtAKYtcWjuqg | W12: 1Uzt32vdzpwWtCvlMdeebxtAKYtcWjuqg
A13: Cover | B13: 1HYgKE8KHG3aHa5yssRP5QkYSCkixs6Iv | C13: 1RTlmvtOz279OOwW6rzsKi07hzWmbIFdE | D13: 1tZYdQCEeHiMObOUF-vn2Zx_IAgH-pQe2 | E13: 121Q8rdnvAjNHDkawLfHg1IAV8Ay02DxJ | F13: 1ykOtB1Lzao_-YY5kILRep2J-yduW-yvd | G13: 1ykOtB1Lzao_-YY5kILRep2J-yduW-yvd | H13: 1ykOtB1Lzao_-YY5kILRep2J-yduW-yvd | I13: 1liZVn5ML72uIAoAhHkp-gcvV2PUbMxIC | J13: 1Ge-0kbMlbbq3Mm6u9ueKITY5H0oFxbXU | K13: 1ykOtB1Lzao_-YY5kILRep2J-yduW-yvd | L13: 1Uzt32vdzpwWtCvlMdeebxtAKYtcWjuqg | M13: 1ykOtB1Lzao_-YY5kILRep2J-yduW-yvd | N13: 1ykOtB1Lzao_-YY5kILRep2J-yduW-yvd | O13: 1FPVSF11YWp7DV9SCG-6uUx43KYfhn84i | P13: 1zeczUMlzYUAQv6t1ZFF7jlnsLiPswUow | Q13: 1ykOtB1Lzao_-YY5kILRep2J-yduW-yvd | R13: 1FPVSF11YWp7DV9SCG-6uUx43KYfhn84i | S13: 19dJbRq6GVwGrt9mZJ3NegsuriQ7G57vt | T13: 1epreGeMwReI4rZGEjathYmZXj34jDL67 | U13: 1HYgKE8KHG3aHa5yssRP5QkYSCkixs6Iv | V13: 1R-P27joAfrXZ_BAAoXefChIegp_RFoFW | W13: 1qUXWXlXls6AuziR3mRgM2QESSlalhpSF
... A23: B-Roll | B23: 1HYgKE8KHG3aHa5yssRP5QkYSCkixs6Iv | C23: 1HYgKE8KHG3aHa5yssRP5QkYSCkixs6Iv | D23: 1HYgKE8KHG3aHa5yssRP5QkYSCkixs6Iv | E23: 1HYgKE8KHG3aHa5yssRP5QkYSCkixs6Iv | F23: 19dJbRq6GVwGrt9mZJ3NegsuriQ7G57vt | G23: 1HYgKE8KHG3aHa5yssRP5QkYSCkixs6Iv | H23: 1HYgKE8KHG3aHa5yssRP5QkYSCkixs6Iv | I23: 19dJbRq6GVwGrt9mZJ3NegsuriQ7G57vt | J23: 1HYgKE8KHG3aHa5yssRP5QkYSCkixs6Iv | K23: 1HYgKE8KHG3aHa5yssRP5QkYSCkixs6Iv | L23: 1Uzt32vdzpwWtCvlMdeebxtAKYtcWjuqg | M23: 1HYgKE8KHG3aHa5yssRP5QkYSCkixs6Iv | N23: 1HYgKE8KHG3aHa5yssRP5QkYSCkixs6Iv | O23: 1FPVSF11YWp7DV9SCG-6uUx43KYfhn84i | P23: 1HYgKE8KHG3aHa5yssRP5QkYSCkixs6Iv | Q23: 1HYgKE8KHG3aHa5yssRP5QkYSCkixs6Iv | R23: 1FPVSF11YWp7DV9SCG-6uUx43KYfhn84i | S23: 1HYgKE8KHG3aHa5yssRP5QkYSCkixs6Iv | T23: 1HYgKE8KHG3aHa5yssRP5QkYSCkixs6Iv | U23: 19dJbRq6GVwGrt9mZJ3NegsuriQ7G57vt | V23: 1HYgKE8KHG3aHa5yssRP5QkYSCkixs6Iv | W23: 1HYgKE8KHG3aHa5yssRP5QkYSCkixs6Iv

Sheet MAYA ids
A1: Admin | B1: 1Uzt32vdzpwWtCvlMdeebxtAKYtcWjuqg
A3: Book - Painting Celia | B3: 1HYgKE8KHG3aHa5yssRP5QkYSCkixs6Iv
A4: – Master | B4: 1P9Cw8CVk7RmkFUfRl3O401cXSLHI2UCZ
A6: Book - Sailor's Code | B6: 1tZYdQCEeHiMObOUF-vn2Zx_IAgH-pQe2
A7: – Images | B7: 10-l2HN5-JdQ1wdyNFcAqKZSjXjALfSYK
A8: – – inspo board | B8: 1rhSpHnbdGgoIfhTgPch_sURRbLSaOXNr
A9: – Master | B9: 1ZD8JgY96Ki6Hj89V-mWlQWouqHANze93
A10: – Old Drafts | B10: 1bPQhvonXrOuVejyMlMUVGfUN6WhSALQh
A12: Book - Untitled Kelsey | B12: 1RTlmvtOz279OOwW6rzsKi07hzWmbIFdE
A13: – Master | B13: 1DFhdaCYC_iJgfjdYpxcsFzWAFicWQ8rq
A15: Marketing | B15: 1liZVn5ML72uIAoAhHkp-gcvV2PUbMxIC
A16: – Headshots | B16: 1zeczUMlzYUAQv6t1ZFF7jlnsLiPswUow
... A38: ~old | B38: 1FPVSF11YWp7DV9SCG-6uUx43KYfhn84i

Sheet LYNN
A1: [LYNN] | B1: =A2 -> Hallway-of-Doorknobs | C1: =A3 -> Untitled-Libby | D1: =A4 -> Workbook | E1: Source | F1: Asset | G1: Copy | H1: Design | I1: Marketing | J1: Newsletter | K1: Inspo | L1: Admin | M1: Cover | N1: Info | O1: Backup | P1: Headshot | Q1: Interior | R1: OLD | S1: Video | T1: PSD | U1: Featured-image | V1: Social-image | W1: B-Roll
A2: Hallway-of-Doorknobs | B2: Book - Hallway of Doorknobs | C2: Unsorted | D2: Unsorted | E2: Source files | F2: Book - Hallway of Doorknobs | G2: Book - Hallway of Doorknobs | H2: Book - Hallway of Doorknobs | I2: Marketing | J2: Marketing | K2: Book - Hallway of Doorknobs | L2: Admin | M2: Book - Hallway of Doorknobs | N2: Book - Hallway of Doorknobs | O2: Book - Hallway of Doorknobs | P2: – Headshots | Q2: Book - Hallway of Doorknobs | R2: OLD | S2: – Video | T2: PSDs | U2: – Assets | V2: – Assets | W2: – Assets
A3: Untitled-Libby | B3: Unsorted | C3: Book - Untitled Libby | D3: Unsorted | E3: Source files | F3: Book - Untitled Libby | G3: Book - Untitled Libby | H3: Book - Untitled Libby | I3: Marketing | J3: Marketing | K3: Book - Untitled Libby | L3: Admin | M3: Book - Untitled Libby | N3: Book - Untitled Libby | O3: Book - Untitled Libby | P3: – Headshots | Q3: Book - Untitled Libby | R3: OLD | S3: – Video | T3: PSDs | U3: – Assets | V3: – Assets | W3: – Assets
A4: Workbook | B4: Unsorted | C4: Unsorted | D4: Book - Workbook | E4: Source files | F4: Book - Workbook | G4: Book - Workbook | H4: Book - Workbook | I4: Marketing | J4: Marketing | K4: Book - Workbook | L4: Admin | M4: Book - Workbook | N4: Book - Workbook | O4: Book - Workbook | P4: – Headshots | Q4: Book - Workbook | R4: OLD | S4: – Video | T4: PSDs | U4: – Assets | V4: – Assets | W4: – Assets
A5: Source | B5: Source files | C5: Source files | D5: Source files | E5: Source files | F5: Source files | G5: Source files | H5: Source files | I5: Source files | J5: Source files | K5: Source files | L5: Source files | M5: Source files | N5: Source files | O5: Source files | P5: Source files | Q5: Source files | R5: OLD | S5: Source files | T5: Source files | U5: Source files | V5: Source files | W5: Source files
A6: Asset | B6: Book - Hallway of Doorknobs | C6: Book - Untitled Libby | D6: Book - Workbook | E6: Source files | F6: – Assets | G6: – Assets | H6: – Assets | I6: – Assets | J6: – Assets | K6: – Assets | L6: Admin | M6: – Assets | N6: – Assets | O6: OLD | P6: – Headshots | Q6: – Assets | R6: OLD | S6: – Video | T6: PSDs | U6: – Assets | V6: – Assets | W6: – Assets
A7: Copy | B7: Book - Hallway of Doorknobs | C7: Book - Untitled Libby | D7: Book - Workbook | E7: Source files | F7: – Assets | G7: – Copy | H7: – Copy | I7: – Copy | J7: – Copy | K7: – Copy | L7: Admin | M7: – Copy | N7: – Copy | O7: OLD | P7: – Headshots | Q7: – Copy | R7: OLD | S7: – Video | T7: PSDs | U7: – Assets | V7: – Assets | W7: – Assets
A8: Design | B8: Book - Hallway of Doorknobs | C8: Book - Untitled Libby | D8: Book - Workbook | E8: Source files | F8: – Assets | G8: – Copy | H8: – Design | I8: – Design | J8: – Design | K8: – Design | L8: Admin | M8: – Design | N8: – Design | O8: OLD | P8: – Headshots | Q8: – Design | R8: OLD | S8: – Video | T8: PSDs | U8: – Assets | V8: – Assets | W8: – Assets
A9: Marketing | B9: Marketing | C9: Marketing | D9: Marketing | E9: Source files | F9: – Assets | G9: – Copy | H9: – Design | I9: Marketing | J9: Marketing | K9: Marketing | L9: Admin | M9: Marketing | N9: Marketing | O9: OLD | P9: – Headshots | Q9: Marketing | R9: OLD | S9: – Video | T9: PSDs | U9: – Assets | V9: – Assets | W9: – Assets
A10: Newsletter | B10: Marketing | C10: Marketing | D10: Marketing | E10: Source files | F10: – Assets | G10: – Copy | H10: – Design | I10: Marketing | J10: Marketing | K10: Marketing | L10: Admin | M10: Marketing | N10: Marketing | O10: OLD | P10: – Headshots | Q10: Marketing | R10: OLD | S10: – Video | T10: PSDs | U10: – Assets | V10: – Assets | W10: – Assets
A11: Inspo | B11: Book - Hallway of Doorknobs | C11: Book - Untitled Libby | D11: Book - Workbook | E11: Source files | F11: – Assets | G11: – Copy | H11: – Design | I11: Marketing | J11: Marketing | K11: Unsorted | L11: Admin | M11: Unsorted | N11: Unsorted | O11: OLD | P11: – Headshots | Q11: Unsorted | R11: OLD | S11: – Video | T11: PSDs | U11: – Assets | V11: – Assets | W11: – Assets
A12: Admin | B12: Admin | C12: Admin | D12: Admin | E12: Source files | F12: Admin | G12: Admin | H12: Admin | I12: Admin | J12: Admin | K12: Admin | L12: Admin | M12: Admin | N12: Admin | O12: OLD | P12: Admin | Q12: Admin | R12: OLD | S12: Admin | T12: PSDs | U12: Admin | V12: Admin | W12: Admin
A13: Cover | B13: Book - Hallway of Doorknobs | C13: Book - Untitled Libby | D13: Book - Workbook | E13: Source files | F13: – Assets | G13: – Copy | H13: – Design | I13: Marketing | J13: Marketing | K13: Unsorted | L13: Admin | M13: Unsorted | N13: Unsorted | O13: OLD | P13: – Headshots | Q13: Unsorted | R13: OLD | S13: – Video | T13: PSDs | U13: – Assets | V13: – Assets | W13: – Assets
... A23: B-Roll | B23: – Assets | C23: – Assets | D23: – Assets | E23: Source files | F23: – Assets | G23: – Assets | H23: – Assets | I23: – Assets | J23: – Assets | K23: – Assets | L23: Admin | M23: – Assets | N23: – Assets | O23: – Assets | P23: – Assets | Q23: – Assets | R23: OLD | S23: – Video | T23: PSDs | U23: – Assets | V23: – Assets | W23: – Assets

Sheet LYNN ids
A1: OLD | B1: 1WJLQaqCT-dbigvaPr0qwSqfWa2okmQuj
A2: Admin | B2: 1h1RSiSTe8nrUgL9drpkfcOyaHLW0Vmr5
A3: Book - Hallway of Doorknobs | B3: 1pvum72Gav0Uo8l2Gv7XqWLHAcp7ebOav
A4: – HoD Master | B4: 1dM3Pt_wGXjnnlbfBPJI8dieMraaQL4C1
A5: Book - Untitled Libby | B5: 1i6YgttRUxsS8eDzNreRHS1kLyFjc8Vbm
A6: – Libby Master | B6: 1wexIzo5Ussu7VuYyqOhS6MYq6MINi23o
A7: Book - Workbook | B7: 1_8XrgWpWpUec4gny3ZkWdj64jT2GJa9c
A8: – Workbook Master | B8: 1hsALaGE1uMGEfF8hxLBG-nvKpEPQGgR3
A9: Marketing | B9: 1nuzqw-fwBX5MyYFA7SCpoxlQ8wv3TzCW
A10: – Headshots | B10: 1hy21y43nwHZaLegDb93aDROu37Vp1JTn
A11: – Video | B11: 1eErACYiOk3jQ2x4SoXSaidAA-qkmTaCG
A12: PSDs | B12: 1fVOTDgQc_VukLst1Vj82KytYqi_ziha0
... A20: – Design | B20: 1Vcm6nyosh52PWrXYbZw0z1hhlfD5bNIo

Sheet LYNN final
A1: [LYNN] | B1: =A2 -> Hallway-of-Doorknobs | C1: =A3 -> Untitled-Libby | D1: =A4 -> Workbook | E1: Source | F1: Asset | G1: Copy | H1: Design | I1: Marketing | J1: Newsletter | K1: Inspo | L1: Admin | M1: Cover | N1: Info | O1: Backup | P1: Headshot | Q1: Interior | R1: OLD | S1: Video | T1: PSD | U1: Featured-image | V1: Social-image | W1: B-Roll
A2: Hallway-of-Doorknobs | B2: =IF(LYNN!B2="","",_xlfn.XLOOKUP(LYNN!B2,'LYNN ids'!$A$1:$A$20,'LYNN ids'!$B$1:$B$20,"")) -> 1pvum72Gav0Uo8l2Gv7XqWLHAcp7ebOav | C2: =IF(LYNN!C2="","",_xlfn.XLOOKUP(LYNN!C2,'LYNN ids'!$A$1:$A$20,'LYNN ids'!$B$1:$B$20,"")) -> 1tp5aFpswfMYtgc_L4jUzXybzxgwJf2_t | D2: =IF(LYNN!D2="","",_xlfn.XLOOKUP(LYNN!D2,'LYNN ids'!$A$1:$A$20,'LYNN ids'!$B$1:$B$20,"")) -> 1tp5aFpswfMYtgc_L4jUzXybzxgwJf2_t | E2: =IF(LYNN!E2="","",_xlfn.XLOOKUP(LYNN!E2,'LYNN ids'!$A$1:$A$20,'LYNN ids'!$B$1:$B$20,"")) -> 1I_HVTZQRAf_MjuUMOLp5geQoy-HQGOs5 | F2: =IF(LYNN!F2="","",_xlfn.XLOOKUP(LYNN!F2,'LYNN ids'!$A$1:$A$20,'LYNN ids'!$B$1:$B$20,"")) -> 1pvum72Gav0Uo8l2Gv7XqWLHAcp7ebOav | G2: =IF(LYNN!G2="","",_xlfn.XLOOKUP(LYNN!G2,'LYNN ids'!$A$1:$A$20,'LYNN ids'!$B$1:$B$20,"")) -> 1pvum72Gav0Uo8l2Gv7XqWLHAcp7ebOav | H2: =IF(LYNN!H2="","",_xlfn.XLOOKUP(LYNN!H2,'LYNN ids'!$A$1:$A$20,'LYNN ids'!$B$1:$B$20,"")) -> 1pvum72Gav0Uo8l2Gv7XqWLHAcp7ebOav | I2: =IF(LYNN!I2="","",_xlfn.XLOOKUP(LYNN!I2,'LYNN ids'!$A$1:$A$20,'LYNN ids'!$B$1:$B$20,"")) -> 1nuzqw-fwBX5MyYFA7SCpoxlQ8wv3TzCW | ... W2: =IF(LYNN!W2="","",_xlfn.XLOOKUP(LYNN!W2,'LYNN ids'!$A$1:$A$20,'LYNN ids'!$B$1:$B$20,"")) -> 14uCOjuWxxahpyW0J5tCTsPM_LD3cvxyr
A3: Untitled-Libby | B3: =IF(LYNN!B3="","",_xlfn.XLOOKUP(LYNN!B3,'LYNN ids'!$A$1:$A$20,'LYNN ids'!$B$1:$B$20,"")) -> 1tp5aFpswfMYtgc_L4jUzXybzxgwJf2_t | C3: =IF(LYNN!C3="","",_xlfn.XLOOKUP(LYNN!C3,'LYNN ids'!$A$1:$A$20,'LYNN ids'!$B$1:$B$20,"")) -> 1i6YgttRUxsS8eDzNreRHS1kLyFjc8Vbm | D3: =IF(LYNN!D3="","",_xlfn.XLOOKUP(LYNN!D3,'LYNN ids'!$A$1:$A$20,'LYNN ids'!$B$1:$B$20,"")) -> 1tp5aFpswfMYtgc_L4jUzXybzxgwJf2_t | E3: =IF(LYNN!E3="","",_xlfn.XLOOKUP(LYNN!E3,'LYNN ids'!$A$1:$A$20,'LYNN ids'!$B$1:$B$20,"")) -> 1I_HVTZQRAf_MjuUMOLp5geQoy-HQGOs5 | F3: =IF(LYNN!F3="","",_xlfn.XLOOKUP(LYNN!F3,'LYNN ids'!$A$1:$A$20,'LYNN ids'!$B$1:$B$20,"")) -> 1i6YgttRUxsS8eDzNreRHS1kLyFjc8Vbm | G3: =IF(LYNN!G3="","",_xlfn.XLOOKUP(LYNN!G3,'LYNN ids'!$A$1:$A$20,'LYNN ids'!$B$1:$B$20,"")) -> 1i6YgttRUxsS8eDzNreRHS1kLyFjc8Vbm | H3: =IF(LYNN!H3="","",_xlfn.XLOOKUP(LYNN!H3,'LYNN ids'!$A$1:$A$20,'LYNN ids'!$B$1:$B$20,"")) -> 1i6YgttRUxsS8eDzNreRHS1kLyFjc8Vbm | I3: =IF(LYNN!I3="","",_xlfn.XLOOKUP(LYNN!I3,'LYNN ids'!$A$1:$A$20,'LYNN ids'!$B$1:$B$20,"")) -> 1nuzqw-fwBX5MyYFA7SCpoxlQ8wv3TzCW | ... W3: =IF(LYNN!W3="","",_xlfn.XLOOKUP(LYNN!W3,'LYNN ids'!$A$1:$A$20,'LYNN ids'!$B$1:$B$20,"")) -> 14uCOjuWxxahpyW0J5tCTsPM_LD3cvxyr
A4: Workbook | B4: =IF(LYNN!B4="","",_xlfn.XLOOKUP(LYNN!B4,'LYNN ids'!$A$1:$A$20,'LYNN ids'!$B$1:$B$20,"")) -> 1tp5aFpswfMYtgc_L4jUzXybzxgwJf2_t | C4: =IF(LYNN!C4="","",_xlfn.XLOOKUP(LYNN!C4,'LYNN ids'!$A$1:$A$20,'LYNN ids'!$B$1:$B$20,"")) -> 1tp5aFpswfMYtgc_L4jUzXybzxgwJf2_t | D4: =IF(LYNN!D4="","",_xlfn.XLOOKUP(LYNN!D4,'LYNN ids'!$A$1:$A$20,'LYNN ids'!$B$1:$B$20,"")) -> 1_8XrgWpWpUec4gny3ZkWdj64jT2GJa9c | E4: =IF(LYNN!E4="","",_xlfn.XLOOKUP(LYNN!E4,'LYNN ids'!$A$1:$A$20,'LYNN ids'!$B$1:$B$20,"")) -> 1I_HVTZQRAf_MjuUMOLp5geQoy-HQGOs5 | F4: =IF(LYNN!F4="","",_xlfn.XLOOKUP(LYNN!F4,'LYNN ids'!$A$1:$A$20,'LYNN ids'!$B$1:$B$20,"")) -> 1_8XrgWpWpUec4gny3ZkWdj64jT2GJa9c | G4: =IF(LYNN!G4="","",_xlfn.XLOOKUP(LYNN!G4,'LYNN ids'!$A$1:$A$20,'LYNN ids'!$B$1:$B$20,"")) -> 1_8XrgWpWpUec4gny3ZkWdj64jT2GJa9c | H4: =IF(LYNN!H4="","",_xlfn.XLOOKUP(LYNN!H4,'LYNN ids'!$A$1:$A$20,'LYNN ids'!$B$1:$B$20,"")) -> 1_8XrgWpWpUec4gny3ZkWdj64jT2GJa9c | I4: =IF(LYNN!I4="","",_xlfn.XLOOKUP(LYNN!I4,'LYNN ids'!$A$1:$A$20,'LYNN ids'!$B$1:$B$20,"")) -> 1nuzqw-fwBX5MyYFA7SCpoxlQ8wv3TzCW | ... W4: =IF(LYNN!W4="","",_xlfn.XLOOKUP(LYNN!W4,'LYNN ids'!$A$1:$A$20,'LYNN ids'!$B$1:$B$20,"")) -> 14uCOjuWxxahpyW0J5tCTsPM_LD3cvxyr
A5: Source | B5: =IF(LYNN!B5="","",_xlfn.XLOOKUP(LYNN!B5,'LYNN ids'!$A$1:$A$20,'LYNN ids'!$B$1:$B$20,"")) -> 1I_HVTZQRAf_MjuUMOLp5geQoy-HQGOs5 | C5: =IF(LYNN!C5="","",_xlfn.XLOOKUP(LYNN!C5,'LYNN ids'!$A$1:$A$20,'LYNN ids'!$B$1:$B$20,"")) -> 1I_HVTZQRAf_MjuUMOLp5geQoy-HQGOs5 | D5: =IF(LYNN!D5="","",_xlfn.XLOOKUP(LYNN!D5,'LYNN ids'!$A$1:$A$20,'LYNN ids'!$B$1:$B$20,"")) -> 1I_HVTZQRAf_MjuUMOLp5geQoy-HQGOs5 | E5: =IF(LYNN!E5="","",_xlfn.XLOOKUP(LYNN!E5,'LYNN ids'!$A$1:$A$20,'LYNN ids'!$B$1:$B$20,"")) -> 1I_HVTZQRAf_MjuUMOLp5geQoy-HQGOs5 | F5: =IF(LYNN!F5="","",_xlfn.XLOOKUP(LYNN!F5,'LYNN ids'!$A$1:$A$20,'LYNN ids'!$B$1:$B$20,"")) -> 1I_HVTZQRAf_MjuUMOLp5geQoy-HQGOs5 | G5: =IF(LYNN!G5="","",_xlfn.XLOOKUP(LYNN!G5,'LYNN ids'!$A$1:$A$20,'LYNN ids'!$B$1:$B$20,"")) -> 1I_HVTZQRAf_MjuUMOLp5geQoy-HQGOs5 | H5: =IF(LYNN!H5="","",_xlfn.XLOOKUP(LYNN!H5,'LYNN ids'!$A$1:$A$20,'LYNN ids'!$B$1:$B$20,"")) -> 1I_HVTZQRAf_MjuUMOLp5geQoy-HQGOs5 | I5: =IF(LYNN!I5="","",_xlfn.XLOOKUP(LYNN!I5,'LYNN ids'!$A$1:$A$20,'LYNN ids'!$B$1:$B$20,"")) -> 1I_HVTZQRAf_MjuUMOLp5geQoy-HQGOs5 | ... W5: =IF(LYNN!W5="","",_xlfn.XLOOKUP(LYNN!W5,'LYNN ids'!$A$1:$A$20,'LYNN ids'!$B$1:$B$20,"")) -> 1I_HVTZQRAf_MjuUMOLp5geQoy-HQGOs5
A6: Asset | B6: =IF(LYNN!B6="","",_xlfn.XLOOKUP(LYNN!B6,'LYNN ids'!$A$1:$A$20,'LYNN ids'!$B$1:$B$20,"")) -> 1pvum72Gav0Uo8l2Gv7XqWLHAcp7ebOav | C6: =IF(LYNN!C6="","",_xlfn.XLOOKUP(LYNN!C6,'LYNN ids'!$A$1:$A$20,'LYNN ids'!$B$1:$B$20,"")) -> 1i6YgttRUxsS8eDzNreRHS1kLyFjc8Vbm | D6: =IF(LYNN!D6="","",_xlfn.XLOOKUP(LYNN!D6,'LYNN ids'!$A$1:$A$20,'LYNN ids'!$B$1:$B$20,"")) -> 1_8XrgWpWpUec4gny3ZkWdj64jT2GJa9c | E6: =IF(LYNN!E6="","",_xlfn.XLOOKUP(LYNN!E6,'LYNN ids'!$A$1:$A$20,'LYNN ids'!$B$1:$B$20,"")) -> 1I_HVTZQRAf_MjuUMOLp5geQoy-HQGOs5 | F6: =IF(LYNN!F6="","",_xlfn.XLOOKUP(LYNN!F6,'LYNN ids'!$A$1:$A$20,'LYNN ids'!$B$1:$B$20,"")) -> 14uCOjuWxxahpyW0J5tCTsPM_LD3cvxyr | G6: =IF(LYNN!G6="","",_xlfn.XLOOKUP(LYNN!G6,'LYNN ids'!$A$1:$A$20,'LYNN ids'!$B$1:$B$20,"")) -> 14uCOjuWxxahpyW0J5tCTsPM_LD3cvxyr | H6: =IF(LYNN!H6="","",_xlfn.XLOOKUP(LYNN!H6,'LYNN ids'!$A$1:$A$20,'LYNN ids'!$B$1:$B$20,"")) -> 14uCOjuWxxahpyW0J5tCTsPM_LD3cvxyr | I6: =IF(LYNN!I6="","",_xlfn.XLOOKUP(LYNN!I6,'LYNN ids'!$A$1:$A$20,'LYNN ids'!$B$1:$B$20,"")) -> 14uCOjuWxxahpyW0J5tCTsPM_LD3cvxyr | ... W6: =IF(LYNN!W6="","",_xlfn.XLOOKUP(LYNN!W6,'LYNN ids'!$A$1:$A$20,'LYNN ids'!$B$1:$B$20,"")) -> 14uCOjuWxxahpyW0J5tCTsPM_LD3cvxyr
A7: Copy | B7: =IF(LYNN!B7="","",_xlfn.XLOOKUP(LYNN!B7,'LYNN ids'!$A$1:$A$20,'LYNN ids'!$B$1:$B$20,"")) -> 1pvum72Gav0Uo8l2Gv7XqWLHAcp7ebOav | C7: =IF(LYNN!C7="","",_xlfn.XLOOKUP(LYNN!C7,'LYNN ids'!$A$1:$A$20,'LYNN ids'!$B$1:$B$20,"")) -> 1i6YgttRUxsS8eDzNreRHS1kLyFjc8Vbm | D7: =IF(LYNN!D7="","",_xlfn.XLOOKUP(LYNN!D7,'LYNN ids'!$A$1:$A$20,'LYNN ids'!$B$1:$B$20,"")) -> 1_8XrgWpWpUec4gny3ZkWdj64jT2GJa9c | E7: =IF(LYNN!E7="","",_xlfn.XLOOKUP(LYNN!E7,'LYNN ids'!$A$1:$A$20,'LYNN ids'!$B$1:$B$20,"")) -> 1I_HVTZQRAf_MjuUMOLp5geQoy-HQGOs5 | F7: =IF(LYNN!F7="","",_xlfn.XLOOKUP(LYNN!F7,'LYNN ids'!$A$1:$A$20,'LYNN ids'!$B$1:$B$20,"")) -> 14uCOjuWxxahpyW0J5tCTsPM_LD3cvxyr | G7: =IF(LYNN!G7="","",_xlfn.XLOOKUP(LYNN!G7,'LYNN ids'!$A$1:$A$20,'LYNN ids'!$B$1:$B$20,"")) -> 1TlC1fMx-wUCxZY1xZiY0DEtoBfOgTShm | H7: =IF(LYNN!H7="","",_xlfn.XLOOKUP(LYNN!H7,'LYNN ids'!$A$1:$A$20,'LYNN ids'!$B$1:$B$20,"")) -> 1TlC1fMx-wUCxZY1xZiY0DEtoBfOgTShm | I7: =IF(LYNN!I7="","",_xlfn.XLOOKUP(LYNN!I7,'LYNN ids'!$A$1:$A$20,'LYNN ids'!$B$1:$B$20,"")) -> 1TlC1fMx-wUCxZY1xZiY0DEtoBfOgTShm | ... W7: =IF(LYNN!W7="","",_xlfn.XLOOKUP(LYNN!W7,'LYNN ids'!$A$1:$A$20,'LYNN ids'!$B$1:$B$20,"")) -> 14uCOjuWxxahpyW0J5tCTsPM_LD3cvxyr
A8: Design | B8: =IF(LYNN!B8="","",_xlfn.XLOOKUP(LYNN!B8,'LYNN ids'!$A$1:$A$20,'LYNN ids'!$B$1:$B$20,"")) -> 1pvum72Gav0Uo8l2Gv7XqWLHAcp7ebOav | C8: =IF(LYNN!C8="","",_xlfn.XLOOKUP(LYNN!C8,'LYNN ids'!$A$1:$A$20,'LYNN ids'!$B$1:$B$20,"")) -> 1i6YgttRUxsS8eDzNreRHS1kLyFjc8Vbm | D8: =IF(LYNN!D8="","",_xlfn.XLOOKUP(LYNN!D8,'LYNN ids'!$A$1:$A$20,'LYNN ids'!$B$1:$B$20,"")) -> 1_8XrgWpWpUec4gny3ZkWdj64jT2GJa9c | E8: =IF(LYNN!E8="","",_xlfn.XLOOKUP(LYNN!E8,'LYNN ids'!$A$1:$A$20,'LYNN ids'!$B$1:$B$20,"")) -> 1I_HVTZQRAf_MjuUMOLp5geQoy-HQGOs5 | F8: =IF(LYNN!F8="","",_xlfn.XLOOKUP(LYNN!F8,'LYNN ids'!$A$1:$A$20,'LYNN ids'!$B$1:$B$20,"")) -> 14uCOjuWxxahpyW0J5tCTsPM_LD3cvxyr | G8: =IF(LYNN!G8="","",_xlfn.XLOOKUP(LYNN!G8,'LYNN ids'!$A$1:$A$20,'LYNN ids'!$B$1:$B$20,"")) -> 1TlC1fMx-wUCxZY1xZiY0DEtoBfOgTShm | H8: =IF(LYNN!H8="","",_xlfn.XLOOKUP(LYNN!H8,'LYNN ids'!$A$1:$A$20,'LYNN ids'!$B$1:$B$20,"")) -> 1Vcm6nyosh52PWrXYbZw0z1hhlfD5bNIo | I8: =IF(LYNN!I8="","",_xlfn.XLOOKUP(LYNN!I8,'LYNN ids'!$A$1:$A$20,'LYNN ids'!$B$1:$B$20,"")) -> 1Vcm6nyosh52PWrXYbZw0z1hhlfD5bNIo | ... W8: =IF(LYNN!W8="","",_xlfn.XLOOKUP(LYNN!W8,'LYNN ids'!$A$1:$A$20,'LYNN ids'!$B$1:$B$20,"")) -> 14uCOjuWxxahpyW0J5tCTsPM_LD3cvxyr
A9: Marketing | B9: =IF(LYNN!B9="","",_xlfn.XLOOKUP(LYNN!B9,'LYNN ids'!$A$1:$A$20,'LYNN ids'!$B$1:$B$20,"")) -> 1nuzqw-fwBX5MyYFA7SCpoxlQ8wv3TzCW | C9: =IF(LYNN!C9="","",_xlfn.XLOOKUP(LYNN!C9,'LYNN ids'!$A$1:$A$20,'LYNN ids'!$B$1:$B$20,"")) -> 1nuzqw-fwBX5MyYFA7SCpoxlQ8wv3TzCW | D9: =IF(LYNN!D9="","",_xlfn.XLOOKUP(LYNN!D9,'LYNN ids'!$A$1:$A$20,'LYNN ids'!$B$1:$B$20,"")) -> 1nuzqw-fwBX5MyYFA7SCpoxlQ8wv3TzCW | E9: =IF(LYNN!E9="","",_xlfn.XLOOKUP(LYNN!E9,'LYNN ids'!$A$1:$A$20,'LYNN ids'!$B$1:$B$20,"")) -> 1I_HVTZQRAf_MjuUMOLp5geQoy-HQGOs5 | F9: =IF(LYNN!F9="","",_xlfn.XLOOKUP(LYNN!F9,'LYNN ids'!$A$1:$A$20,'LYNN ids'!$B$1:$B$20,"")) -> 14uCOjuWxxahpyW0J5tCTsPM_LD3cvxyr | G9: =IF(LYNN!G9="","",_xlfn.XLOOKUP(LYNN!G9,'LYNN ids'!$A$1:$A$20,'LYNN ids'!$B$1:$B$20,"")) -> 1TlC1fMx-wUCxZY1xZiY0DEtoBfOgTShm | H9: =IF(LYNN!H9="","",_xlfn.XLOOKUP(LYNN!H9,'LYNN ids'!$A$1:$A$20,'LYNN ids'!$B$1:$B$20,"")) -> 1Vcm6nyosh52PWrXYbZw0z1hhlfD5bNIo | I9: =IF(LYNN!I9="","",_xlfn.XLOOKUP(LYNN!I9,'LYNN ids'!$A$1:$A$20,'LYNN ids'!$B$1:$B$20,"")) -> 1nuzqw-fwBX5MyYFA7SCpoxlQ8wv3TzCW | ... W9: =IF(LYNN!W9="","",_xlfn.XLOOKUP(LYNN!W9,'LYNN ids'!$A$1:$A$20,'LYNN ids'!$B$1:$B$20,"")) -> 14uCOjuWxxahpyW0J5tCTsPM_LD3cvxyr
A10: Newsletter | B10: =IF(LYNN!B10="","",_xlfn.XLOOKUP(LYNN!B10,'LYNN ids'!$A$1:$A$20,'LYNN ids'!$B$1:$B$20,"")) -> 1nuzqw-fwBX5MyYFA7SCpoxlQ8wv3TzCW | C10: =IF(LYNN!C10="","",_xlfn.XLOOKUP(LYNN!C10,'LYNN ids'!$A$1:$A$20,'LYNN ids'!$B$1:$B$20,"")) -> 1nuzqw-fwBX5MyYFA7SCpoxlQ8wv3TzCW | D10: =IF(LYNN!D10="","",_xlfn.XLOOKUP(LYNN!D10,'LYNN ids'!$A$1:$A$20,'LYNN ids'!$B$1:$B$20,"")) -> 1nuzqw-fwBX5MyYFA7SCpoxlQ8wv3TzCW | E10: =IF(LYNN!E10="","",_xlfn.XLOOKUP(LYNN!E10,'LYNN ids'!$A$1:$A$20,'LYNN ids'!$B$1:$B$20,"")) -> 1I_HVTZQRAf_MjuUMOLp5geQoy-HQGOs5 | F10: =IF(LYNN!F10="","",_xlfn.XLOOKUP(LYNN!F10,'LYNN ids'!$A$1:$A$20,'LYNN ids'!$B$1:$B$20,"")) -> 14uCOjuWxxahpyW0J5tCTsPM_LD3cvxyr | G10: =IF(LYNN!G10="","",_xlfn.XLOOKUP(LYNN!G10,'LYNN ids'!$A$1:$A$20,'LYNN ids'!$B$1:$B$20,"")) -> 1TlC1fMx-wUCxZY1xZiY0DEtoBfOgTShm | H10: =IF(LYNN!H10="","",_xlfn.XLOOKUP(LYNN!H10,'LYNN ids'!$A$1:$A$20,'LYNN ids'!$B$1:$B$20,"")) -> 1Vcm6nyosh52PWrXYbZw0z1hhlfD5bNIo | I10: =IF(LYNN!I10="","",_xlfn.XLOOKUP(LYNN!I10,'LYNN ids'!$A$1:$A$20,'LYNN ids'!$B$1:$B$20,"")) -> 1nuzqw-fwBX5MyYFA7SCpoxlQ8wv3TzCW | ... W10: =IF(LYNN!W10="","",_xlfn.XLOOKUP(LYNN!W10,'LYNN ids'!$A$1:$A$20,'LYNN ids'!$B$1:$B$20,"")) -> 14uCOjuWxxahpyW0J5tCTsPM_LD3cvxyr
A11: Inspo | B11: =IF(LYNN!B11="","",_xlfn.XLOOKUP(LYNN!B11,'LYNN ids'!$A$1:$A$20,'LYNN ids'!$B$1:$B$20,"")) -> 1pvum72Gav0Uo8l2Gv7XqWLHAcp7ebOav | C11: =IF(LYNN!C11="","",_xlfn.XLOOKUP(LYNN!C11,'LYNN ids'!$A$1:$A$20,'LYNN ids'!$B$1:$B$20,"")) -> 1i6YgttRUxsS8eDzNreRHS1kLyFjc8Vbm | D11: =IF(LYNN!D11="","",_xlfn.XLOOKUP(LYNN!D11,'LYNN ids'!$A$1:$A$20,'LYNN ids'!$B$1:$B$20,"")) -> 1_8XrgWpWpUec4gny3ZkWdj64jT2GJa9c | E11: =IF(LYNN!E11="","",_xlfn.XLOOKUP(LYNN!E11,'LYNN ids'!$A$1:$A$20,'LYNN ids'!$B$1:$B$20,"")) -> 1I_HVTZQRAf_MjuUMOLp5geQoy-HQGOs5 | F11: =IF(LYNN!F11="","",_xlfn.XLOOKUP(LYNN!F11,'LYNN ids'!$A$1:$A$20,'LYNN ids'!$B$1:$B$20,"")) -> 14uCOjuWxxahpyW0J5tCTsPM_LD3cvxyr | G11: =IF(LYNN!G11="","",_xlfn.XLOOKUP(LYNN!G11,'LYNN ids'!$A$1:$A$20,'LYNN ids'!$B$1:$B$20,"")) -> 1TlC1fMx-wUCxZY1xZiY0DEtoBfOgTShm | H11: =IF(LYNN!H11="","",_xlfn.XLOOKUP(LYNN!H11,'LYNN ids'!$A$1:$A$20,'LYNN ids'!$B$1:$B$20,"")) -> 1Vcm6nyosh52PWrXYbZw0z1hhlfD5bNIo | I11: =IF(LYNN!I11="","",_xlfn.XLOOKUP(LYNN!I11,'LYNN ids'!$A$1:$A$20,'LYNN ids'!$B$1:$B$20,"")) -> 1nuzqw-fwBX5MyYFA7SCpoxlQ8wv3TzCW | ... W11: =IF(LYNN!W11="","",_xlfn.XLOOKUP(LYNN!W11,'LYNN ids'!$A$1:$A$20,'LYNN ids'!$B$1:$B$20,"")) -> 14uCOjuWxxahpyW0J5tCTsPM_LD3cvxyr
A12: Admin | B12: =IF(LYNN!B12="","",_xlfn.XLOOKUP(LYNN!B12,'LYNN ids'!$A$1:$A$20,'LYNN ids'!$B$1:$B$20,"")) -> 1h1RSiSTe8nrUgL9drpkfcOyaHLW0Vmr5 | C12: =IF(LYNN!C12="","",_xlfn.XLOOKUP(LYNN!C12,'LYNN ids'!$A$1:$A$20,'LYNN ids'!$B$1:$B$20,"")) -> 1h1RSiSTe8nrUgL9drpkfcOyaHLW0Vmr5 | D12: =IF(LYNN!D12="","",_xlfn.XLOOKUP(LYNN!D12,'LYNN ids'!$A$1:$A$20,'LYNN ids'!$B$1:$B$20,"")) -> 1h1RSiSTe8nrUgL9drpkfcOyaHLW0Vmr5 | E12: =IF(LYNN!E12="","",_xlfn.XLOOKUP(LYNN!E12,'LYNN ids'!$A$1:$A$20,'LYNN ids'!$B$1:$B$20,"")) -> 1I_HVTZQRAf_MjuUMOLp5geQoy-HQGOs5 | F12: =IF(LYNN!F12="","",_xlfn.XLOOKUP(LYNN!F12,'LYNN ids'!$A$1:$A$20,'LYNN ids'!$B$1:$B$20,"")) -> 1h1RSiSTe8nrUgL9drpkfcOyaHLW0Vmr5 | G12: =IF(LYNN!G12="","",_xlfn.XLOOKUP(LYNN!G12,'LYNN ids'!$A$1:$A$20,'LYNN ids'!$B$1:$B$20,"")) -> 1h1RSiSTe8nrUgL9drpkfcOyaHLW0Vmr5 | H12: =IF(LYNN!H12="","",_xlfn.XLOOKUP(LYNN!H12,'LYNN ids'!$A$1:$A$20,'LYNN ids'!$B$1:$B$20,"")) -> 1h1RSiSTe8nrUgL9drpkfcOyaHLW0Vmr5 | I12: =IF(LYNN!I12="","",_xlfn.XLOOKUP(LYNN!I12,'LYNN ids'!$A$1:$A$20,'LYNN ids'!$B$1:$B$20,"")) -> 1h1RSiSTe8nrUgL9drpkfcOyaHLW0Vmr5 | ... W12: =IF(LYNN!W12="","",_xlfn.XLOOKUP(LYNN!W12,'LYNN ids'!$A$1:$A$20,'LYNN ids'!$B$1:$B$20,"")) -> 1h1RSiSTe8nrUgL9drpkfcOyaHLW0Vmr5
A13: Cover | B13: =IF(LYNN!B13="","",_xlfn.XLOOKUP(LYNN!B13,'LYNN ids'!$A$1:$A$20,'LYNN ids'!$B$1:$B$20,"")) -> 1pvum72Gav0Uo8l2Gv7XqWLHAcp7ebOav | C13: =IF(LYNN!C13="","",_xlfn.XLOOKUP(LYNN!C13,'LYNN ids'!$A$1:$A$20,'LYNN ids'!$B$1:$B$20,"")) -> 1i6YgttRUxsS8eDzNreRHS1kLyFjc8Vbm | D13: =IF(LYNN!D13="","",_xlfn.XLOOKUP(LYNN!D13,'LYNN ids'!$A$1:$A$20,'LYNN ids'!$B$1:$B$20,"")) -> 1_8XrgWpWpUec4gny3ZkWdj64jT2GJa9c | E13: =IF(LYNN!E13="","",_xlfn.XLOOKUP(LYNN!E13,'LYNN ids'!$A$1:$A$20,'LYNN ids'!$B$1:$B$20,"")) -> 1I_HVTZQRAf_MjuUMOLp5geQoy-HQGOs5 | F13: =IF(LYNN!F13="","",_xlfn.XLOOKUP(LYNN!F13,'LYNN ids'!$A$1:$A$20,'LYNN ids'!$B$1:$B$20,"")) -> 14uCOjuWxxahpyW0J5tCTsPM_LD3cvxyr | G13: =IF(LYNN!G13="","",_xlfn.XLOOKUP(LYNN!G13,'LYNN ids'!$A$1:$A$20,'LYNN ids'!$B$1:$B$20,"")) -> 1TlC1fMx-wUCxZY1xZiY0DEtoBfOgTShm | H13: =IF(LYNN!H13="","",_xlfn.XLOOKUP(LYNN!H13,'LYNN ids'!$A$1:$A$20,'LYNN ids'!$B$1:$B$20,"")) -> 1Vcm6nyosh52PWrXYbZw0z1hhlfD5bNIo | I13: =IF(LYNN!I13="","",_xlfn.XLOOKUP(LYNN!I13,'LYNN ids'!$A$1:$A$20,'LYNN ids'!$B$1:$B$20,"")) -> 1nuzqw-fwBX5MyYFA7SCpoxlQ8wv3TzCW | ... W13: =IF(LYNN!W13="","",_xlfn.XLOOKUP(LYNN!W13,'LYNN ids'!$A$1:$A$20,'LYNN ids'!$B$1:$B$20,"")) -> 14uCOjuWxxahpyW0J5tCTsPM_LD3cvxyr
... A23: B-Roll | B23: =IF(LYNN!B23="","",_xlfn.XLOOKUP(LYNN!B23,'LYNN ids'!$A$1:$A$20,'LYNN ids'!$B$1:$B$20,"")) -> 14uCOjuWxxahpyW0J5tCTsPM_LD3cvxyr | C23: =IF(LYNN!C23="","",_xlfn.XLOOKUP(LYNN!C23,'LYNN ids'!$A$1:$A$20,'LYNN ids'!$B$1:$B$20,"")) -> 14uCOjuWxxahpyW0J5tCTsPM_LD3cvxyr | D23: =IF(LYNN!D23="","",_xlfn.XLOOKUP(LYNN!D23,'LYNN ids'!$A$1:$A$20,'LYNN ids'!$B$1:$B$20,"")) -> 14uCOjuWxxahpyW0J5tCTsPM_LD3cvxyr | E23: =IF(LYNN!E23="","",_xlfn.XLOOKUP(LYNN!E23,'LYNN ids'!$A$1:$A$20,'LYNN ids'!$B$1:$B$20,"")) -> 1I_HVTZQRAf_MjuUMOLp5geQoy-HQGOs5 | F23: =IF(LYNN!F23="","",_xlfn.XLOOKUP(LYNN!F23,'LYNN ids'!$A$1:$A$20,'LYNN ids'!$B$1:$B$20,"")) -> 14uCOjuWxxahpyW0J5tCTsPM_LD3cvxyr | G23: =IF(LYNN!G23="","",_xlfn.XLOOKUP(LYNN!G23,'LYNN ids'!$A$1:$A$20,'LYNN ids'!$B$1:$B$20,"")) -> 14uCOjuWxxahpyW0J5tCTsPM_LD3cvxyr | H23: =IF(LYNN!H23="","",_xlfn.XLOOKUP(LYNN!H23,'LYNN ids'!$A$1:$A$20,'LYNN ids'!$B$1:$B$20,"")) -> 14uCOjuWxxahpyW0J5tCTsPM_LD3cvxyr | I23: =IF(LYNN!I23="","",_xlfn.XLOOKUP(LYNN!I23,'LYNN ids'!$A$1:$A$20,'LYNN ids'!$B$1:$B$20,"")) -> 14uCOjuWxxahpyW0J5tCTsPM_LD3cvxyr | ... W23: =IF(LYNN!W23="","",_xlfn.XLOOKUP(LYNN!W23,'LYNN ids'!$A$1:$A$20,'LYNN ids'!$B$1:$B$20,"")) -> 14uCOjuWxxahpyW0J5tCTsPM_LD3cvxyr

Sheet SULIMA
A1: [SULIMA] | B1: All-in-the-Soup | C1: Arms-Filled-with-Bittersweet | D1: Tributaries | E1: Words-That-Dance | F1: Source | G1: Asset | H1: Copy | I1: Design | J1: Marketing | K1: Newsletter | L1: Inspo | M1: Admin | N1: Cover | O1: Info | P1: Backup | Q1: Headshot | R1: Interior | S1: OLD | T1: Video | U1: PSD | V1: Featured-image | W1: Social-image
A2: All-in-the-Soup | B2: BOOK - All in the Soup Together | C2: Unsorted | D2: Unsorted | E2: Unsorted | F2: Source files | G2: – Assets | H2: – Copy | I2: – Design | J2: Marketing | K2: Marketing | L2: Source files | M2: Admin | N2: BOOK - All in the Soup Together | O2: BOOK - All in the Soup Together | P2: OLD | Q2: Marketing | R2: BOOK - All in the Soup Together | S2: OLD | T2: BOOK - All in the Soup Together | U2: PSDs | V2: – – Featured images | W2: – Social images
A3: Arms-Filled-with-Bittersweet | B3: Unsorted | C3: BOOK - Arms Filled with Bittersweet | D3: Unsorted | E3: Unsorted | F3: Source files | G3: – Assets | H3: – Copy | I3: – Design | J3: Marketing | K3: Marketing | L3: Source files | M3: Admin | N3: BOOK - Arms Filled with Bittersweet | O3: BOOK - Arms Filled with Bittersweet | P3: OLD | Q3: Marketing | R3: BOOK - Arms Filled with Bittersweet | S3: OLD | T3: BOOK - Arms Filled with Bittersweet | U3: PSDs | V3: – – Featured images | W3: – Social images
A4: Tributaries | B4: Unsorted | C4: Unsorted | D4: BOOK - Tributaries | E4: Unsorted | F4: Source files | G4: – Assets | H4: – Copy | I4: – Design | J4: Marketing | K4: Marketing | L4: Source files | M4: Admin | N4: BOOK - Tributaries | O4: BOOK - Tributaries | P4: OLD | Q4: Marketing | R4: BOOK - Tributaries | S4: OLD | T4: BOOK - Tributaries | U4: PSDs | V4: – – Featured images | W4: – Social images
A5: Words-That-Dance | B5: Unsorted | C5: Unsorted | D5: Unsorted | E5: BOOK - Words That Dance | F5: Source files | G5: – Assets | H5: – Copy | I5: – Design | J5: Marketing | K5: Marketing | L5: Source files | M5: Admin | N5: BOOK - Words That Dance | O5: BOOK - Words That Dance | P5: OLD | Q5: Marketing | R5: BOOK - Words That Dance | S5: OLD | T5: BOOK - Words That Dance | U5: PSDs | V5: – – Featured images | W5: – Social images
A6: Source | B6: Source files | C6: Source files | D6: Source files | E6: Source files | F6: Source files | G6: Source files | H6: Source files | I6: Source files | J6: Source files | K6: Source files | L6: Source files | M6: Source files | N6: Source files | O6: Source files | P6: Source files | Q6: Source files | R6: Source files | S6: OLD | T6: Source files | U6: Source files | V6: Source files | W6: Source files
A7: Asset | B7: – Assets | C7: – Assets | D7: – Assets | E7: – Assets | F7: Source files | G7: – Assets | H7: – Copy | I7: – Design | J7: – Assets | K7: – Assets | L7: – Assets | M7: Admin | N7: – Assets | O7: – Assets | P7: OLD | Q7: Marketing | R7: – Assets | S7: OLD | T7: – Assets | U7: PSDs | V7: – – Featured images | W7: – Social images
A8: Copy | B8: – Copy | C8: – Copy | D8: – Copy | E8: – Copy | F8: Source files | G8: – Copy | H8: – Copy | I8: – Design | J8: – Copy | K8: – Copy | L8: – Copy | M8: Admin | N8: – Copy | O8: – Copy | P8: OLD | Q8: Marketing | R8: – Copy | S8: OLD | T8: – Copy | U8: PSDs | V8: – – Featured images | W8: – Social images
A9: Design | B9: – Design | C9: – Design | D9: – Design | E9: – Design | F9: Source files | G9: – Design | H9: – Design | I9: – Design | J9: – Design | K9: – Design | L9: – Design | M9: Admin | N9: – Design | O9: – Design | P9: OLD | Q9: Marketing | R9: – Design | S9: OLD | T9: – Design | U9: PSDs | V9: – – Featured images | W9: – Social images
A10: Marketing | B10: Marketing | C10: Marketing | D10: Marketing | E10: Marketing | F10: Source files | G10: – Assets | H10: – Copy | I10: – Design | J10: Marketing | K10: Marketing | L10: Marketing | M10: Admin | N10: Marketing | O10: Marketing | P10: OLD | Q10: Marketing | R10: Marketing | S10: OLD | T10: Marketing | U10: PSDs | V10: – – Featured images | W10: – Social images
A11: Newsletter | B11: Marketing | C11: Marketing | D11: Marketing | E11: Marketing | F11: Source files | G11: – Assets | H11: – Copy | I11: – Design | J11: Marketing | K11: Marketing | L11: Marketing | M11: Admin | N11: Marketing | O11: Marketing | P11: OLD | Q11: Marketing | R11: Marketing | S11: OLD | T11: Marketing | U11: PSDs | V11: – – Featured images | W11: – Social images
A12: Inspo | B12: Source files | C12: Source files | D12: Source files | E12: Source files | F12: Source files | G12: – Assets | H12: – Copy | I12: – Design | J12: Marketing | K12: Marketing | L12: – Assets | M12: Admin | N12: Source files | O12: Source files | P12: OLD | Q12: Marketing | R12: Source files | S12: OLD | T12: Source files | U12: PSDs | V12: – – Featured images | W12: – Social images
... A23: Social-image | B23: – Social images | C23: – Social images | D23: – Social images | E23: – Social images | F23: Source files | G23: – Social images | H23: – Social images | I23: – Social images | J23: – Social images | K23: – Social images | L23: – Social images | M23: – Social images | N23: – Social images | O23: – Social images | P23: OLD | Q23: – Social images | R23: – Social images | S23: OLD | T23: – Social images | U23: PSDs | V23: – – Featured images | W23: – Social images

Sheet SULIMA ids
A1: OLD | B1: 1ASTrMyT8BoZ1R3JFTD4faPJqC2wAwo-Z
A2: Admin | B2: 1Wwn62wgXvWL4xPfCsCRGLl2nGC6yMHnn
A3: PSDs | B3: 1D4VHUORJN08hK49qS1ZCEZ0CwV7aMR_h
A4: SHARED | B4: 1nNs4IL7Vrx_xuRxmKE-kCqmBizvBMgcV
A5: Source files | B5: 1oa1DjYEEwdm9wJQW8XDZUDk4jrqlG5QB
A6: Unsorted | B6: 1R0aAzfFYL8pB08eBBG09IYcExjLDE6S1
A7: BOOK - All in the Soup Together | B7: 1wXYsN253TZTVcBPueU0Ayy595L3WR3SH
A8: – Master | B8: 1K9TPBa4lpwe68-HcLdtSPkCvSAq1NpiD
A9: BOOK - Tributaries | B9: 1yF_yKsQkQwSwIIPflP8B1nITKy_4MrH1
A10: – Master | B10: 1gsjBBx9eGQhjyLE8wL2lONLQNUy5reeX
A11: BOOK - Words That Dance | B11: 1XVA06M6iqqw1tnHE74sTIg-4I-kQXmaC
A12: – Master | B12: 1IMsYiNNUoUZFAp_H6uP80d_Az1XCjckc
... A21: – Social images | B21: 1NT5GSrqVKJwtOsn6fTB5iZOyxdGqUWbh

Sheet SULIMA final
A1: [SULIMA] | B1: =SULIMA!B1 -> All-in-the-Soup | C1: =SULIMA!C1 -> Arms-Filled-with-Bittersweet | D1: =SULIMA!D1 -> Tributaries | E1: =SULIMA!E1 -> Words-That-Dance | F1: =SULIMA!F1 -> Source | G1: =SULIMA!G1 -> Asset | H1: =SULIMA!H1 -> Copy | I1: =SULIMA!I1 -> Design | ... W1: =SULIMA!W1 -> Social-image
A2: =SULIMA!A2 -> All-in-the-Soup | B2: =IF(SULIMA!B2="","",_xlfn.XLOOKUP(SULIMA!B2,'SULIMA ids'!$A$1:$A$21,'SULIMA ids'!$B$1:$B$21,"")) -> 1wXYsN253TZTVcBPueU0Ayy595L3WR3SH | C2: =IF(SULIMA!C2="","",_xlfn.XLOOKUP(SULIMA!C2,'SULIMA ids'!$A$1:$A$21,'SULIMA ids'!$B$1:$B$21,"")) -> 1R0aAzfFYL8pB08eBBG09IYcExjLDE6S1 | D2: =IF(SULIMA!D2="","",_xlfn.XLOOKUP(SULIMA!D2,'SULIMA ids'!$A$1:$A$21,'SULIMA ids'!$B$1:$B$21,"")) -> 1R0aAzfFYL8pB08eBBG09IYcExjLDE6S1 | E2: =IF(SULIMA!E2="","",_xlfn.XLOOKUP(SULIMA!E2,'SULIMA ids'!$A$1:$A$21,'SULIMA ids'!$B$1:$B$21,"")) -> 1R0aAzfFYL8pB08eBBG09IYcExjLDE6S1 | F2: =IF(SULIMA!F2="","",_xlfn.XLOOKUP(SULIMA!F2,'SULIMA ids'!$A$1:$A$21,'SULIMA ids'!$B$1:$B$21,"")) -> 1oa1DjYEEwdm9wJQW8XDZUDk4jrqlG5QB | G2: =IF(SULIMA!G2="","",_xlfn.XLOOKUP(SULIMA!G2,'SULIMA ids'!$A$1:$A$21,'SULIMA ids'!$B$1:$B$21,"")) -> 17eP1Ps9zdVPnVgQdYS3YuaFMui4sbtPi | H2: =IF(SULIMA!H2="","",_xlfn.XLOOKUP(SULIMA!H2,'SULIMA ids'!$A$1:$A$21,'SULIMA ids'!$B$1:$B$21,"")) -> 1jibhxXBXsZUgsTYiudGBCjD7cdAILiiA | I2: =IF(SULIMA!I2="","",_xlfn.XLOOKUP(SULIMA!I2,'SULIMA ids'!$A$1:$A$21,'SULIMA ids'!$B$1:$B$21,"")) -> 1Wxi1Qx2VmUJJRXaACsUpIwCwLL-MeLSh | ... W2: =IF(SULIMA!W2="","",_xlfn.XLOOKUP(SULIMA!W2,'SULIMA ids'!$A$1:$A$21,'SULIMA ids'!$B$1:$B$21,"")) -> 1NT5GSrqVKJwtOsn6fTB5iZOyxdGqUWbh
A3: =SULIMA!A3 -> Arms-Filled-with-Bittersweet | B3: =IF(SULIMA!B3="","",_xlfn.XLOOKUP(SULIMA!B3,'SULIMA ids'!$A$1:$A$21,'SULIMA ids'!$B$1:$B$21,"")) -> 1R0aAzfFYL8pB08eBBG09IYcExjLDE6S1 | C3: =IF(SULIMA!C3="","",_xlfn.XLOOKUP(SULIMA!C3,'SULIMA ids'!$A$1:$A$21,'SULIMA ids'!$B$1:$B$21,"")) -> 1z-sFkqO7SWcgnPRxaJAk1jziLahxBLWo | D3: =IF(SULIMA!D3="","",_xlfn.XLOOKUP(SULIMA!D3,'SULIMA ids'!$A$1:$A$21,'SULIMA ids'!$B$1:$B$21,"")) -> 1R0aAzfFYL8pB08eBBG09IYcExjLDE6S1 | E3: =IF(SULIMA!E3="","",_xlfn.XLOOKUP(SULIMA!E3,'SULIMA ids'!$A$1:$A$21,'SULIMA ids'!$B$1:$B$21,"")) -> 1R0aAzfFYL8pB08eBBG09IYcExjLDE6S1 | F3: =IF(SULIMA!F3="","",_xlfn.XLOOKUP(SULIMA!F3,'SULIMA ids'!$A$1:$A$21,'SULIMA ids'!$B$1:$B$21,"")) -> 1oa1DjYEEwdm9wJQW8XDZUDk4jrqlG5QB | G3: =IF(SULIMA!G3="","",_xlfn.XLOOKUP(SULIMA!G3,'SULIMA ids'!$A$1:$A$21,'SULIMA ids'!$B$1:$B$21,"")) -> 17eP1Ps9zdVPnVgQdYS3YuaFMui4sbtPi | H3: =IF(SULIMA!H3="","",_xlfn.XLOOKUP(SULIMA!H3,'SULIMA ids'!$A$1:$A$21,'SULIMA ids'!$B$1:$B$21,"")) -> 1jibhxXBXsZUgsTYiudGBCjD7cdAILiiA | I3: =IF(SULIMA!I3="","",_xlfn.XLOOKUP(SULIMA!I3,'SULIMA ids'!$A$1:$A$21,'SULIMA ids'!$B$1:$B$21,"")) -> 1Wxi1Qx2VmUJJRXaACsUpIwCwLL-MeLSh | ... W3: =IF(SULIMA!W3="","",_xlfn.XLOOKUP(SULIMA!W3,'SULIMA ids'!$A$1:$A$21,'SULIMA ids'!$B$1:$B$21,"")) -> 1NT5GSrqVKJwtOsn6fTB5iZOyxdGqUWbh
A4: =SULIMA!A4 -> Tributaries | B4: =IF(SULIMA!B4="","",_xlfn.XLOOKUP(SULIMA!B4,'SULIMA ids'!$A$1:$A$21,'SULIMA ids'!$B$1:$B$21,"")) -> 1R0aAzfFYL8pB08eBBG09IYcExjLDE6S1 | C4: =IF(SULIMA!C4="","",_xlfn.XLOOKUP(SULIMA!C4,'SULIMA ids'!$A$1:$A$21,'SULIMA ids'!$B$1:$B$21,"")) -> 1R0aAzfFYL8pB08eBBG09IYcExjLDE6S1 | D4: =IF(SULIMA!D4="","",_xlfn.XLOOKUP(SULIMA!D4,'SULIMA ids'!$A$1:$A$21,'SULIMA ids'!$B$1:$B$21,"")) -> 1yF_yKsQkQwSwIIPflP8B1nITKy_4MrH1 | E4: =IF(SULIMA!E4="","",_xlfn.XLOOKUP(SULIMA!E4,'SULIMA ids'!$A$1:$A$21,'SULIMA ids'!$B$1:$B$21,"")) -> 1R0aAzfFYL8pB08eBBG09IYcExjLDE6S1 | F4: =IF(SULIMA!F4="","",_xlfn.XLOOKUP(SULIMA!F4,'SULIMA ids'!$A$1:$A$21,'SULIMA ids'!$B$1:$B$21,"")) -> 1oa1DjYEEwdm9wJQW8XDZUDk4jrqlG5QB | G4: =IF(SULIMA!G4="","",_xlfn.XLOOKUP(SULIMA!G4,'SULIMA ids'!$A$1:$A$21,'SULIMA ids'!$B$1:$B$21,"")) -> 17eP1Ps9zdVPnVgQdYS3YuaFMui4sbtPi | H4: =IF(SULIMA!H4="","",_xlfn.XLOOKUP(SULIMA!H4,'SULIMA ids'!$A$1:$A$21,'SULIMA ids'!$B$1:$B$21,"")) -> 1jibhxXBXsZUgsTYiudGBCjD7cdAILiiA | I4: =IF(SULIMA!I4="","",_xlfn.XLOOKUP(SULIMA!I4,'SULIMA ids'!$A$1:$A$21,'SULIMA ids'!$B$1:$B$21,"")) -> 1Wxi1Qx2VmUJJRXaACsUpIwCwLL-MeLSh | ... W4: =IF(SULIMA!W4="","",_xlfn.XLOOKUP(SULIMA!W4,'SULIMA ids'!$A$1:$A$21,'SULIMA ids'!$B$1:$B$21,"")) -> 1NT5GSrqVKJwtOsn6fTB5iZOyxdGqUWbh
A5: =SULIMA!A5 -> Words-That-Dance | B5: =IF(SULIMA!B5="","",_xlfn.XLOOKUP(SULIMA!B5,'SULIMA ids'!$A$1:$A$21,'SULIMA ids'!$B$1:$B$21,"")) -> 1R0aAzfFYL8pB08eBBG09IYcExjLDE6S1 | C5: =IF(SULIMA!C5="","",_xlfn.XLOOKUP(SULIMA!C5,'SULIMA ids'!$A$1:$A$21,'SULIMA ids'!$B$1:$B$21,"")) -> 1R0aAzfFYL8pB08eBBG09IYcExjLDE6S1 | D5: =IF(SULIMA!D5="","",_xlfn.XLOOKUP(SULIMA!D5,'SULIMA ids'!$A$1:$A$21,'SULIMA ids'!$B$1:$B$21,"")) -> 1R0aAzfFYL8pB08eBBG09IYcExjLDE6S1 | E5: =IF(SULIMA!E5="","",_xlfn.XLOOKUP(SULIMA!E5,'SULIMA ids'!$A$1:$A$21,'SULIMA ids'!$B$1:$B$21,"")) -> 1XVA06M6iqqw1tnHE74sTIg-4I-kQXmaC | F5: =IF(SULIMA!F5="","",_xlfn.XLOOKUP(SULIMA!F5,'SULIMA ids'!$A$1:$A$21,'SULIMA ids'!$B$1:$B$21,"")) -> 1oa1DjYEEwdm9wJQW8XDZUDk4jrqlG5QB | G5: =IF(SULIMA!G5="","",_xlfn.XLOOKUP(SULIMA!G5,'SULIMA ids'!$A$1:$A$21,'SULIMA ids'!$B$1:$B$21,"")) -> 17eP1Ps9zdVPnVgQdYS3YuaFMui4sbtPi | H5: =IF(SULIMA!H5="","",_xlfn.XLOOKUP(SULIMA!H5,'SULIMA ids'!$A$1:$A$21,'SULIMA ids'!$B$1:$B$21,"")) -> 1jibhxXBXsZUgsTYiudGBCjD7cdAILiiA | I5: =IF(SULIMA!I5="","",_xlfn.XLOOKUP(SULIMA!I5,'SULIMA ids'!$A$1:$A$21,'SULIMA ids'!$B$1:$B$21,"")) -> 1Wxi1Qx2VmUJJRXaACsUpIwCwLL-MeLSh | ... W5: =IF(SULIMA!W5="","",_xlfn.XLOOKUP(SULIMA!W5,'SULIMA ids'!$A$1:$A$21,'SULIMA ids'!$B$1:$B$21,"")) -> 1NT5GSrqVKJwtOsn6fTB5iZOyxdGqUWbh
A6: =SULIMA!A6 -> Source | B6: =IF(SULIMA!B6="","",_xlfn.XLOOKUP(SULIMA!B6,'SULIMA ids'!$A$1:$A$21,'SULIMA ids'!$B$1:$B$21,"")) -> 1oa1DjYEEwdm9wJQW8XDZUDk4jrqlG5QB | C6: =IF(SULIMA!C6="","",_xlfn.XLOOKUP(SULIMA!C6,'SULIMA ids'!$A$1:$A$21,'SULIMA ids'!$B$1:$B$21,"")) -> 1oa1DjYEEwdm9wJQW8XDZUDk4jrqlG5QB | D6: =IF(SULIMA!D6="","",_xlfn.XLOOKUP(SULIMA!D6,'SULIMA ids'!$A$1:$A$21,'SULIMA ids'!$B$1:$B$21,"")) -> 1oa1DjYEEwdm9wJQW8XDZUDk4jrqlG5QB | E6: =IF(SULIMA!E6="","",_xlfn.XLOOKUP(SULIMA!E6,'SULIMA ids'!$A$1:$A$21,'SULIMA ids'!$B$1:$B$21,"")) -> 1oa1DjYEEwdm9wJQW8XDZUDk4jrqlG5QB | F6: =IF(SULIMA!F6="","",_xlfn.XLOOKUP(SULIMA!F6,'SULIMA ids'!$A$1:$A$21,'SULIMA ids'!$B$1:$B$21,"")) -> 1oa1DjYEEwdm9wJQW8XDZUDk4jrqlG5QB | G6: =IF(SULIMA!G6="","",_xlfn.XLOOKUP(SULIMA!G6,'SULIMA ids'!$A$1:$A$21,'SULIMA ids'!$B$1:$B$21,"")) -> 1oa1DjYEEwdm9wJQW8XDZUDk4jrqlG5QB | H6: =IF(SULIMA!H6="","",_xlfn.XLOOKUP(SULIMA!H6,'SULIMA ids'!$A$1:$A$21,'SULIMA ids'!$B$1:$B$21,"")) -> 1oa1DjYEEwdm9wJQW8XDZUDk4jrqlG5QB | I6: =IF(SULIMA!I6="","",_xlfn.XLOOKUP(SULIMA!I6,'SULIMA ids'!$A$1:$A$21,'SULIMA ids'!$B$1:$B$21,"")) -> 1oa1DjYEEwdm9wJQW8XDZUDk4jrqlG5QB | ... W6: =IF(SULIMA!W6="","",_xlfn.XLOOKUP(SULIMA!W6,'SULIMA ids'!$A$1:$A$21,'SULIMA ids'!$B$1:$B$21,"")) -> 1oa1DjYEEwdm9wJQW8XDZUDk4jrqlG5QB
A7: =SULIMA!A7 -> Asset | B7: =IF(SULIMA!B7="","",_xlfn.XLOOKUP(SULIMA!B7,'SULIMA ids'!$A$1:$A$21,'SULIMA ids'!$B$1:$B$21,"")) -> 17eP1Ps9zdVPnVgQdYS3YuaFMui4sbtPi | C7: =IF(SULIMA!C7="","",_xlfn.XLOOKUP(SULIMA!C7,'SULIMA ids'!$A$1:$A$21,'SULIMA ids'!$B$1:$B$21,"")) -> 17eP1Ps9zdVPnVgQdYS3YuaFMui4sbtPi | D7: =IF(SULIMA!D7="","",_xlfn.XLOOKUP(SULIMA!D7,'SULIMA ids'!$A$1:$A$21,'SULIMA ids'!$B$1:$B$21,"")) -> 17eP1Ps9zdVPnVgQdYS3YuaFMui4sbtPi | E7: =IF(SULIMA!E7="","",_xlfn.XLOOKUP(SULIMA!E7,'SULIMA ids'!$A$1:$A$21,'SULIMA ids'!$B$1:$B$21,"")) -> 17eP1Ps9zdVPnVgQdYS3YuaFMui4sbtPi | F7: =IF(SULIMA!F7="","",_xlfn.XLOOKUP(SULIMA!F7,'SULIMA ids'!$A$1:$A$21,'SULIMA ids'!$B$1:$B$21,"")) -> 1oa1DjYEEwdm9wJQW8XDZUDk4jrqlG5QB | G7: =IF(SULIMA!G7="","",_xlfn.XLOOKUP(SULIMA!G7,'SULIMA ids'!$A$1:$A$21,'SULIMA ids'!$B$1:$B$21,"")) -> 17eP1Ps9zdVPnVgQdYS3YuaFMui4sbtPi | H7: =IF(SULIMA!H7="","",_xlfn.XLOOKUP(SULIMA!H7,'SULIMA ids'!$A$1:$A$21,'SULIMA ids'!$B$1:$B$21,"")) -> 1jibhxXBXsZUgsTYiudGBCjD7cdAILiiA | I7: =IF(SULIMA!I7="","",_xlfn.XLOOKUP(SULIMA!I7,'SULIMA ids'!$A$1:$A$21,'SULIMA ids'!$B$1:$B$21,"")) -> 1Wxi1Qx2VmUJJRXaACsUpIwCwLL-MeLSh | ... W7: =IF(SULIMA!W7="","",_xlfn.XLOOKUP(SULIMA!W7,'SULIMA ids'!$A$1:$A$21,'SULIMA ids'!$B$1:$B$21,"")) -> 1NT5GSrqVKJwtOsn6fTB5iZOyxdGqUWbh
A8: =SULIMA!A8 -> Copy | B8: =IF(SULIMA!B8="","",_xlfn.XLOOKUP(SULIMA!B8,'SULIMA ids'!$A$1:$A$21,'SULIMA ids'!$B$1:$B$21,"")) -> 1jibhxXBXsZUgsTYiudGBCjD7cdAILiiA | C8: =IF(SULIMA!C8="","",_xlfn.XLOOKUP(SULIMA!C8,'SULIMA ids'!$A$1:$A$21,'SULIMA ids'!$B$1:$B$21,"")) -> 1jibhxXBXsZUgsTYiudGBCjD7cdAILiiA | D8: =IF(SULIMA!D8="","",_xlfn.XLOOKUP(SULIMA!D8,'SULIMA ids'!$A$1:$A$21,'SULIMA ids'!$B$1:$B$21,"")) -> 1jibhxXBXsZUgsTYiudGBCjD7cdAILiiA | E8: =IF(SULIMA!E8="","",_xlfn.XLOOKUP(SULIMA!E8,'SULIMA ids'!$A$1:$A$21,'SULIMA ids'!$B$1:$B$21,"")) -> 1jibhxXBXsZUgsTYiudGBCjD7cdAILiiA | F8: =IF(SULIMA!F8="","",_xlfn.XLOOKUP(SULIMA!F8,'SULIMA ids'!$A$1:$A$21,'SULIMA ids'!$B$1:$B$21,"")) -> 1oa1DjYEEwdm9wJQW8XDZUDk4jrqlG5QB | G8: =IF(SULIMA!G8="","",_xlfn.XLOOKUP(SULIMA!G8,'SULIMA ids'!$A$1:$A$21,'SULIMA ids'!$B$1:$B$21,"")) -> 1jibhxXBXsZUgsTYiudGBCjD7cdAILiiA | H8: =IF(SULIMA!H8="","",_xlfn.XLOOKUP(SULIMA!H8,'SULIMA ids'!$A$1:$A$21,'SULIMA ids'!$B$1:$B$21,"")) -> 1jibhxXBXsZUgsTYiudGBCjD7cdAILiiA | I8: =IF(SULIMA!I8="","",_xlfn.XLOOKUP(SULIMA!I8,'SULIMA ids'!$A$1:$A$21,'SULIMA ids'!$B$1:$B$21,"")) -> 1Wxi1Qx2VmUJJRXaACsUpIwCwLL-MeLSh | ... W8: =IF(SULIMA!W8="","",_xlfn.XLOOKUP(SULIMA!W8,'SULIMA ids'!$A$1:$A$21,'SULIMA ids'!$B$1:$B$21,"")) -> 1NT5GSrqVKJwtOsn6fTB5iZOyxdGqUWbh
A9: =SULIMA!A9 -> Design | B9: =IF(SULIMA!B9="","",_xlfn.XLOOKUP(SULIMA!B9,'SULIMA ids'!$A$1:$A$21,'SULIMA ids'!$B$1:$B$21,"")) -> 1Wxi1Qx2VmUJJRXaACsUpIwCwLL-MeLSh | C9: =IF(SULIMA!C9="","",_xlfn.XLOOKUP(SULIMA!C9,'SULIMA ids'!$A$1:$A$21,'SULIMA ids'!$B$1:$B$21,"")) -> 1Wxi1Qx2VmUJJRXaACsUpIwCwLL-MeLSh | D9: =IF(SULIMA!D9="","",_xlfn.XLOOKUP(SULIMA!D9,'SULIMA ids'!$A$1:$A$21,'SULIMA ids'!$B$1:$B$21,"")) -> 1Wxi1Qx2VmUJJRXaACsUpIwCwLL-MeLSh | E9: =IF(SULIMA!E9="","",_xlfn.XLOOKUP(SULIMA!E9,'SULIMA ids'!$A$1:$A$21,'SULIMA ids'!$B$1:$B$21,"")) -> 1Wxi1Qx2VmUJJRXaACsUpIwCwLL-MeLSh | F9: =IF(SULIMA!F9="","",_xlfn.XLOOKUP(SULIMA!F9,'SULIMA ids'!$A$1:$A$21,'SULIMA ids'!$B$1:$B$21,"")) -> 1oa1DjYEEwdm9wJQW8XDZUDk4jrqlG5QB | G9: =IF(SULIMA!G9="","",_xlfn.XLOOKUP(SULIMA!G9,'SULIMA ids'!$A$1:$A$21,'SULIMA ids'!$B$1:$B$21,"")) -> 1Wxi1Qx2VmUJJRXaACsUpIwCwLL-MeLSh | H9: =IF(SULIMA!H9="","",_xlfn.XLOOKUP(SULIMA!H9,'SULIMA ids'!$A$1:$A$21,'SULIMA ids'!$B$1:$B$21,"")) -> 1Wxi1Qx2VmUJJRXaACsUpIwCwLL-MeLSh | I9: =IF(SULIMA!I9="","",_xlfn.XLOOKUP(SULIMA!I9,'SULIMA ids'!$A$1:$A$21,'SULIMA ids'!$B$1:$B$21,"")) -> 1Wxi1Qx2VmUJJRXaACsUpIwCwLL-MeLSh | ... W9: =IF(SULIMA!W9="","",_xlfn.XLOOKUP(SULIMA!W9,'SULIMA ids'!$A$1:$A$21,'SULIMA ids'!$B$1:$B$21,"")) -> 1NT5GSrqVKJwtOsn6fTB5iZOyxdGqUWbh
A10: =SULIMA!A10 -> Marketing | B10: =IF(SULIMA!B10="","",_xlfn.XLOOKUP(SULIMA!B10,'SULIMA ids'!$A$1:$A$21,'SULIMA ids'!$B$1:$B$21,"")) -> 1D4BOx2y0gJ6IaGCUqBoJ6lOROpoXeUL7 | C10: =IF(SULIMA!C10="","",_xlfn.XLOOKUP(SULIMA!C10,'SULIMA ids'!$A$1:$A$21,'SULIMA ids'!$B$1:$B$21,"")) -> 1D4BOx2y0gJ6IaGCUqBoJ6lOROpoXeUL7 | D10: =IF(SULIMA!D10="","",_xlfn.XLOOKUP(SULIMA!D10,'SULIMA ids'!$A$1:$A$21,'SULIMA ids'!$B$1:$B$21,"")) -> 1D4BOx2y0gJ6IaGCUqBoJ6lOROpoXeUL7 | E10: =IF(SULIMA!E10="","",_xlfn.XLOOKUP(SULIMA!E10,'SULIMA ids'!$A$1:$A$21,'SULIMA ids'!$B$1:$B$21,"")) -> 1D4BOx2y0gJ6IaGCUqBoJ6lOROpoXeUL7 | F10: =IF(SULIMA!F10="","",_xlfn.XLOOKUP(SULIMA!F10,'SULIMA ids'!$A$1:$A$21,'SULIMA ids'!$B$1:$B$21,"")) -> 1oa1DjYEEwdm9wJQW8XDZUDk4jrqlG5QB | G10: =IF(SULIMA!G10="","",_xlfn.XLOOKUP(SULIMA!G10,'SULIMA ids'!$A$1:$A$21,'SULIMA ids'!$B$1:$B$21,"")) -> 17eP1Ps9zdVPnVgQdYS3YuaFMui4sbtPi | H10: =IF(SULIMA!H10="","",_xlfn.XLOOKUP(SULIMA!H10,'SULIMA ids'!$A$1:$A$21,'SULIMA ids'!$B$1:$B$21,"")) -> 1jibhxXBXsZUgsTYiudGBCjD7cdAILiiA | I10: =IF(SULIMA!I10="","",_xlfn.XLOOKUP(SULIMA!I10,'SULIMA ids'!$A$1:$A$21,'SULIMA ids'!$B$1:$B$21,"")) -> 1Wxi1Qx2VmUJJRXaACsUpIwCwLL-MeLSh | ... W10: =IF(SULIMA!W10="","",_xlfn.XLOOKUP(SULIMA!W10,'SULIMA ids'!$A$1:$A$21,'SULIMA ids'!$B$1:$B$21,"")) -> 1NT5GSrqVKJwtOsn6fTB5iZOyxdGqUWbh
A11: =SULIMA!A11 -> Newsletter | B11: =IF(SULIMA!B11="","",_xlfn.XLOOKUP(SULIMA!B11,'SULIMA ids'!$A$1:$A$21,'SULIMA ids'!$B$1:$B$21,"")) -> 1D4BOx2y0gJ6IaGCUqBoJ6lOROpoXeUL7 | C11: =IF(SULIMA!C11="","",_xlfn.XLOOKUP(SULIMA!C11,'SULIMA ids'!$A$1:$A$21,'SULIMA ids'!$B$1:$B$21,"")) -> 1D4BOx2y0gJ6IaGCUqBoJ6lOROpoXeUL7 | D11: =IF(SULIMA!D11="","",_xlfn.XLOOKUP(SULIMA!D11,'SULIMA ids'!$A$1:$A$21,'SULIMA ids'!$B$1:$B$21,"")) -> 1D4BOx2y0gJ6IaGCUqBoJ6lOROpoXeUL7 | E11: =IF(SULIMA!E11="","",_xlfn.XLOOKUP(SULIMA!E11,'SULIMA ids'!$A$1:$A$21,'SULIMA ids'!$B$1:$B$21,"")) -> 1D4BOx2y0gJ6IaGCUqBoJ6lOROpoXeUL7 | F11: =IF(SULIMA!F11="","",_xlfn.XLOOKUP(SULIMA!F11,'SULIMA ids'!$A$1:$A$21,'SULIMA ids'!$B$1:$B$21,"")) -> 1oa1DjYEEwdm9wJQW8XDZUDk4jrqlG5QB | G11: =IF(SULIMA!G11="","",_xlfn.XLOOKUP(SULIMA!G11,'SULIMA ids'!$A$1:$A$21,'SULIMA ids'!$B$1:$B$21,"")) -> 17eP1Ps9zdVPnVgQdYS3YuaFMui4sbtPi | H11: =IF(SULIMA!H11="","",_xlfn.XLOOKUP(SULIMA!H11,'SULIMA ids'!$A$1:$A$21,'SULIMA ids'!$B$1:$B$21,"")) -> 1jibhxXBXsZUgsTYiudGBCjD7cdAILiiA | I11: =IF(SULIMA!I11="","",_xlfn.XLOOKUP(SULIMA!I11,'SULIMA ids'!$A$1:$A$21,'SULIMA ids'!$B$1:$B$21,"")) -> 1Wxi1Qx2VmUJJRXaACsUpIwCwLL-MeLSh | ... W11: =IF(SULIMA!W11="","",_xlfn.XLOOKUP(SULIMA!W11,'SULIMA ids'!$A$1:$A$21,'SULIMA ids'!$B$1:$B$21,"")) -> 1NT5GSrqVKJwtOsn6fTB5iZOyxdGqUWbh
A12: =SULIMA!A12 -> Inspo | B12: =IF(SULIMA!B12="","",_xlfn.XLOOKUP(SULIMA!B12,'SULIMA ids'!$A$1:$A$21,'SULIMA ids'!$B$1:$B$21,"")) -> 1oa1DjYEEwdm9wJQW8XDZUDk4jrqlG5QB | C12: =IF(SULIMA!C12="","",_xlfn.XLOOKUP(SULIMA!C12,'SULIMA ids'!$A$1:$A$21,'SULIMA ids'!$B$1:$B$21,"")) -> 1oa1DjYEEwdm9wJQW8XDZUDk4jrqlG5QB | D12: =IF(SULIMA!D12="","",_xlfn.XLOOKUP(SULIMA!D12,'SULIMA ids'!$A$1:$A$21,'SULIMA ids'!$B$1:$B$21,"")) -> 1oa1DjYEEwdm9wJQW8XDZUDk4jrqlG5QB | E12: =IF(SULIMA!E12="","",_xlfn.XLOOKUP(SULIMA!E12,'SULIMA ids'!$A$1:$A$21,'SULIMA ids'!$B$1:$B$21,"")) -> 1oa1DjYEEwdm9wJQW8XDZUDk4jrqlG5QB | F12: =IF(SULIMA!F12="","",_xlfn.XLOOKUP(SULIMA!F12,'SULIMA ids'!$A$1:$A$21,'SULIMA ids'!$B$1:$B$21,"")) -> 1oa1DjYEEwdm9wJQW8XDZUDk4jrqlG5QB | G12: =IF(SULIMA!G12="","",_xlfn.XLOOKUP(SULIMA!G12,'SULIMA ids'!$A$1:$A$21,'SULIMA ids'!$B$1:$B$21,"")) -> 17eP1Ps9zdVPnVgQdYS3YuaFMui4sbtPi | H12: =IF(SULIMA!H12="","",_xlfn.XLOOKUP(SULIMA!H12,'SULIMA ids'!$A$1:$A$21,'SULIMA ids'!$B$1:$B$21,"")) -> 1jibhxXBXsZUgsTYiudGBCjD7cdAILiiA | I12: =IF(SULIMA!I12="","",_xlfn.XLOOKUP(SULIMA!I12,'SULIMA ids'!$A$1:$A$21,'SULIMA ids'!$B$1:$B$21,"")) -> 1Wxi1Qx2VmUJJRXaACsUpIwCwLL-MeLSh | ... W12: =IF(SULIMA!W12="","",_xlfn.XLOOKUP(SULIMA!W12,'SULIMA ids'!$A$1:$A$21,'SULIMA ids'!$B$1:$B$21,"")) -> 1NT5GSrqVKJwtOsn6fTB5iZOyxdGqUWbh
A13: =SULIMA!A13 -> Admin | B13: =IF(SULIMA!B13="","",_xlfn.XLOOKUP(SULIMA!B13,'SULIMA ids'!$A$1:$A$21,'SULIMA ids'!$B$1:$B$21,"")) -> 1Wwn62wgXvWL4xPfCsCRGLl2nGC6yMHnn | C13: =IF(SULIMA!C13="","",_xlfn.XLOOKUP(SULIMA!C13,'SULIMA ids'!$A$1:$A$21,'SULIMA ids'!$B$1:$B$21,"")) -> 1Wwn62wgXvWL4xPfCsCRGLl2nGC6yMHnn | D13: =IF(SULIMA!D13="","",_xlfn.XLOOKUP(SULIMA!D13,'SULIMA ids'!$A$1:$A$21,'SULIMA ids'!$B$1:$B$21,"")) -> 1Wwn62wgXvWL4xPfCsCRGLl2nGC6yMHnn | E13: =IF(SULIMA!E13="","",_xlfn.XLOOKUP(SULIMA!E13,'SULIMA ids'!$A$1:$A$21,'SULIMA ids'!$B$1:$B$21,"")) -> 1Wwn62wgXvWL4xPfCsCRGLl2nGC6yMHnn | F13: =IF(SULIMA!F13="","",_xlfn.XLOOKUP(SULIMA!F13,'SULIMA ids'!$A$1:$A$21,'SULIMA ids'!$B$1:$B$21,"")) -> 1oa1DjYEEwdm9wJQW8XDZUDk4jrqlG5QB | G13: =IF(SULIMA!G13="","",_xlfn.XLOOKUP(SULIMA!G13,'SULIMA ids'!$A$1:$A$21,'SULIMA ids'!$B$1:$B$21,"")) -> 1Wwn62wgXvWL4xPfCsCRGLl2nGC6yMHnn | H13: =IF(SULIMA!H13="","",_xlfn.XLOOKUP(SULIMA!H13,'SULIMA ids'!$A$1:$A$21,'SULIMA ids'!$B$1:$B$21,"")) -> 1Wwn62wgXvWL4xPfCsCRGLl2nGC6yMHnn | I13: =IF(SULIMA!I13="","",_xlfn.XLOOKUP(SULIMA!I13,'SULIMA ids'!$A$1:$A$21,'SULIMA ids'!$B$1:$B$21,"")) -> 1Wwn62wgXvWL4xPfCsCRGLl2nGC6yMHnn | ... W13: =IF(SULIMA!W13="","",_xlfn.XLOOKUP(SULIMA!W13,'SULIMA ids'!$A$1:$A$21,'SULIMA ids'!$B$1:$B$21,"")) -> 1NT5GSrqVKJwtOsn6fTB5iZOyxdGqUWbh
... A23: =SULIMA!A23 -> Social-image | B23: =IF(SULIMA!B23="","",_xlfn.XLOOKUP(SULIMA!B23,'SULIMA ids'!$A$1:$A$21,'SULIMA ids'!$B$1:$B$21,"")) -> 1NT5GSrqVKJwtOsn6fTB5iZOyxdGqUWbh | C23: =IF(SULIMA!C23="","",_xlfn.XLOOKUP(SULIMA!C23,'SULIMA ids'!$A$1:$A$21,'SULIMA ids'!$B$1:$B$21,"")) -> 1NT5GSrqVKJwtOsn6fTB5iZOyxdGqUWbh | D23: =IF(SULIMA!D23="","",_xlfn.XLOOKUP(SULIMA!D23,'SULIMA ids'!$A$1:$A$21,'SULIMA ids'!$B$1:$B$21,"")) -> 1NT5GSrqVKJwtOsn6fTB5iZOyxdGqUWbh | E23: =IF(SULIMA!E23="","",_xlfn.XLOOKUP(SULIMA!E23,'SULIMA ids'!$A$1:$A$21,'SULIMA ids'!$B$1:$B$21,"")) -> 1NT5GSrqVKJwtOsn6fTB5iZOyxdGqUWbh | F23: =IF(SULIMA!F23="","",_xlfn.XLOOKUP(SULIMA!F23,'SULIMA ids'!$A$1:$A$21,'SULIMA ids'!$B$1:$B$21,"")) -> 1oa1DjYEEwdm9wJQW8XDZUDk4jrqlG5QB | G23: =IF(SULIMA!G23="","",_xlfn.XLOOKUP(SULIMA!G23,'SULIMA ids'!$A$1:$A$21,'SULIMA ids'!$B$1:$B$21,"")) -> 1NT5GSrqVKJwtOsn6fTB5iZOyxdGqUWbh | H23: =IF(SULIMA!H23="","",_xlfn.XLOOKUP(SULIMA!H23,'SULIMA ids'!$A$1:$A$21,'SULIMA ids'!$B$1:$B$21,"")) -> 1NT5GSrqVKJwtOsn6fTB5iZOyxdGqUWbh | I23: =IF(SULIMA!I23="","",_xlfn.XLOOKUP(SULIMA!I23,'SULIMA ids'!$A$1:$A$21,'SULIMA ids'!$B$1:$B$21,"")) -> 1NT5GSrqVKJwtOsn6fTB5iZOyxdGqUWbh | ... W23: =IF(SULIMA!W23="","",_xlfn.XLOOKUP(SULIMA!W23,'SULIMA ids'!$A$1:$A$21,'SULIMA ids'!$B$1:$B$21,"")) -> 1NT5GSrqVKJwtOsn6fTB5iZOyxdGqUWbh

Sheet LINGUA INK
A1: [LINGUA INK] | B1: =A2 -> All-in-the-Soup | C1: =A3 -> Arms-Filled-with-Bittersweet | D1: =A4 -> Tributaries | E1: =A5 -> Words-That-Dance | F1: =A6 -> Source | G1: =A7 -> Asset | H1: =A8 -> Copy | I1: =A9 -> Design | J1: =A10 -> Marketing | K1: =A11 -> Newsletter | L1: =A12 -> Inspo | M1: =A13 -> Admin | N1: =A14 -> Cover | O1: =A15 -> Info | P1: =A16 -> Backup | Q1: =A17 -> Headshot | R1: =A18 -> Interior | S1: =A19 -> OLD | T1: =A20 -> Video | U1: =A21 -> PSD | V1: =A22 -> Featured-image | W1: =A23 -> Social-image
A2: All-in-the-Soup | B2: BOOK - All in the Soup Together | C2: Unsorted | D2: Unsorted | E2: Unsorted | F2: Unsorted | G2: Unsorted | H2: Unsorted | I2: Unsorted | J2: Unsorted | K2: Unsorted | L2: Unsorted | M2: Unsorted | N2: Unsorted | O2: Unsorted | P2: Unsorted | Q2: Unsorted | R2: Unsorted | S2: Unsorted | T2: Unsorted | U2: Unsorted | V2: Unsorted | W2: Unsorted
A3: Arms-Filled-with-Bittersweet | B3: Unsorted | C3: BOOK - Arms Filled with Bittersweet | D3: Unsorted | E3: Unsorted | F3: Unsorted | G3: Unsorted | H3: Unsorted | I3: Unsorted | J3: Unsorted | K3: Unsorted | L3: Unsorted | M3: Unsorted | N3: Unsorted | O3: Unsorted | P3: Unsorted | Q3: Unsorted | R3: Unsorted | S3: Unsorted | T3: Unsorted | U3: Unsorted | V3: Unsorted | W3: Unsorted
